Workbook

Sheet Inicio
A1: Matriz AHP – Selección del tema del proyecto final (Eficiencia Energética e IA)
A2: Réplica en Excel del método AHP (Analytic Hierarchy Process) con cálculo del vector propio, razón de consistencia (CR) y análisis de sensibilidad.
A4: Objetivo | B4: Meta | C4: Seleccionar el tema específico del proyecto final sobre optimización de procesos industriales con IA para la eficiencia energética
A6: Criterios (editable)
A7: N° | B7: Nombre del criterio | C7: Descripción
A8: 1 | B8: Pertinencia | C8: Alineación con el perfil de Ing. Industrial y etapa CHECK de ISO 50001
A9: 2 | B9: Datos | C9: Disponibilidad de información, series temporales y datos benchmark
A10: 3 | B10: Viabilidad | C10: Factibilidad técnica, riesgo operativo y requerimientos de cómputo
A11: 4 | B11: Impacto | C11: Aporte de innovación tecnológica, Green AI y explicabilidad (XAI)
A12: 5 | B12: Caso_real | C12: Factibilidad temporal de ejecución en el plazo previsto de 8 a 10 meses
A14: Alternativas (editable)
A15: Código | B15: Nombre del tema | C15: Descripción
A16: A | B16: Prediccion_ML | C16: Tema A: Predicción de consumo energético industrial con Machine Learning
A17: B | B17: Setpoints_RL | C17: Tema B: Optimización de setpoints de proceso con Reinforcement Learning
A18: C | B18: Anomalias_GreenAI | C18: Tema C: Detección de anomalías energéticas con IA y enfoque Green AI
A20: Índice de consistencia aleatorio (RI, Saaty)
A21: n | B21: RI
A22: 1 | B22: 0 | C22: Fuente: valores estándar de Saaty para matrices de 1 a 5 elementos.
A23: 2 | B23: 0
A24: 3 | B24: 0.58
A25: 4 | B25: 0.9
A26: 5 | B26: 1.12
A28: Escala de Saaty
A29: Valor | B29: Significado
A30: 1 | B30: Igual importancia
A31: 3 | B31: Importancia moderada
A32: 5 | B32: Importancia fuerte
A33: 7 | B33: Importancia muy fuerte
A34: 9 | B34: Importancia extrema
A35: 2,4,6,8 | B35: Valores intermedios

Sheet Criterios
A1: ="Comparación por pares de los CRITERIOS respecto al objetivo: "&Inicio!$C$4
A2: Elija en 'Prefiere' cuál es más importante (Izquierda / Derecha / Igual) y en 'Valor' cuánto más (1 a 9, escala de Saaty). Edite solo las celdas amarillas.
A3: Escala: 1 igual · 3 moderada · 5 fuerte · 7 muy fuerte · 9 extrema (2, 4, 6, 8 intermedios).
A5: 1. Juicios de comparación por pares
A6: N° | B6: Izquierda | C6: Derecha | D6: Prefiere | E6: Valor (1-9) | F6: a(i,j) | G6: Lectura
A7: 1 | B7: =Inicio!$B$8 | C7: =Inicio!$B$9 | D7: Igual | E7: 1 | F7: =IF(D7="Izquierda",E7,IF(D7="Derecha",1/E7,1)) | G7: =IF(D7="Igual",B7&" = "&C7,IF(D7="Izquierda",B7&" > "&C7&" (x"&E7&")",C7&" > "&B7&" (x"&E7&")"))
A8: 2 | B8: =Inicio!$B$8 | C8: =Inicio!$B$10 | D8: Igual | E8: 1 | F8: =IF(D8="Izquierda",E8,IF(D8="Derecha",1/E8,1)) | G8: =IF(D8="Igual",B8&" = "&C8,IF(D8="Izquierda",B8&" > "&C8&" (x"&E8&")",C8&" > "&B8&" (x"&E8&")"))
A9: 3 | B9: =Inicio!$B$8 | C9: =Inicio!$B$11 | D9: Izquierda | E9: 2 | F9: =IF(D9="Izquierda",E9,IF(D9="Derecha",1/E9,1)) | G9: =IF(D9="Igual",B9&" = "&C9,IF(D9="Izquierda",B9&" > "&C9&" (x"&E9&")",C9&" > "&B9&" (x"&E9&")"))
A10: 4 | B10: =Inicio!$B$8 | C10: =Inicio!$B$12 | D10: Izquierda | E10: 2 | F10: =IF(D10="Izquierda",E10,IF(D10="Derecha",1/E10,1)) | G10: =IF(D10="Igual",B10&" = "&C10,IF(D10="Izquierda",B10&" > "&C10&" (x"&E10&")",C10&" > "&B10&" (x"&E10&")"))
A11: 5 | B11: =Inicio!$B$9 | C11: =Inicio!$B$10 | D11: Igual | E11: 1 | F11: =IF(D11="Izquierda",E11,IF(D11="Derecha",1/E11,1)) | G11: =IF(D11="Igual",B11&" = "&C11,IF(D11="Izquierda",B11&" > "&C11&" (x"&E11&")",C11&" > "&B11&" (x"&E11&")"))
A12: 6 | B12: =Inicio!$B$9 | C12: =Inicio!$B$11 | D12: Igual | E12: 1 | F12: =IF(D12="Izquierda",E12,IF(D12="Derecha",1/E12,1)) | G12: =IF(D12="Igual",B12&" = "&C12,IF(D12="Izquierda",B12&" > "&C12&" (x"&E12&")",C12&" > "&B12&" (x"&E12&")"))
A13: 7 | B13: =Inicio!$B$9 | C13: =Inicio!$B$12 | D13: Igual | E13: 1 | F13: =IF(D13="Izquierda",E13,IF(D13="Derecha",1/E13,1)) | G13: =IF(D13="Igual",B13&" = "&C13,IF(D13="Izquierda",B13&" > "&C13&" (x"&E13&")",C13&" > "&B13&" (x"&E13&")"))
A14: 8 | B14: =Inicio!$B$10 | C14: =Inicio!$B$11 | D14: Izquierda | E14: 2 | F14: =IF(D14="Izquierda",E14,IF(D14="Derecha",1/E14,1)) | G14: =IF(D14="Igual",B14&" = "&C14,IF(D14="Izquierda",B14&" > "&C14&" (x"&E14&")",C14&" > "&B14&" (x"&E14&")"))
A15: 9 | B15: =Inicio!$B$10 | C15: =Inicio!$B$12 | D15: Izquierda | E15: 2 | F15: =IF(D15="Izquierda",E15,IF(D15="Derecha",1/E15,1)) | G15: =IF(D15="Igual",B15&" = "&C15,IF(D15="Izquierda",B15&" > "&C15&" (x"&E15&")",C15&" > "&B15&" (x"&E15&")"))
A16: 10 | B16: =Inicio!$B$11 | C16: =Inicio!$B$12 | D16: Igual | E16: 1 | F16: =IF(D16="Izquierda",E16,IF(D16="Derecha",1/E16,1)) | G16: =IF(D16="Igual",B16&" = "&C16,IF(D16="Izquierda",B16&" > "&C16&" (x"&E16&")",C16&" > "&B16&" (x"&E16&")"))
A18: 2. Matriz de comparación y prioridades
B19: =Inicio!$B$8 | C19: =Inicio!$B$9 | D19: =Inicio!$B$10 | E19: =Inicio!$B$11 | F19: =Inicio!$B$12 | G19: Prioridad | H19: Posición
A20: =Inicio!$B$8 | B20: 1 | C20: =F7 | D20: =F8 | E20: =F9 | F20: =F10 | G20: =B62 | H20: =RANK(G20,$G$20:$G$24)
A21: =Inicio!$B$9 | B21: =1/C20 | C21: 1 | D21: =F11 | E21: =F12 | F21: =F13 | G21: =C62 | H21: =RANK(G21,$G$20:$G$24)
A22: =Inicio!$B$10 | B22: =1/D20 | C22: =1/D21 | D22: 1 | E22: =F14 | F22: =F15 | G22: =D62 | H22: =RANK(G22,$G$20:$G$24)
A23: =Inicio!$B$11 | B23: =1/E20 | C23: =1/E21 | D23: =1/E22 | E23: 1 | F23: =F16 | G23: =E62 | H23: =RANK(G23,$G$20:$G$24)
A24: =Inicio!$B$12 | B24: =1/F20 | C24: =1/F21 | D24: =1/F22 | E24: =1/F23 | F24: 1 | G24: =F62 | H24: =RANK(G24,$G$20:$G$24)
A25: Suma columna | B25: =SUM(B20:B24) | C25: =SUM(C20:C24) | D25: =SUM(D20:D24) | E25: =SUM(E20:E24) | F25: =SUM(F20:F24)
A27: Consistencia
A28: λ máx | B28: =SUMPRODUCT($B$25:$F$25,$B$62:$F$62)
A29: CI | B29: =(B28-5)/(5-1)
A30: RI | B30: {=INDEX(Inicio!$B$22:$B$26,5)}
A31: CR | B31: =IF(B30=0,0,B29/B30)
A32: Estado | B32: =IF(B31<0.1,"OK (CR < 10 %)","REVISAR: CR ≥ 10 %")
A35: 3. Cálculo del vector propio (método de las potencias, 25 iteraciones)
A36: Iteración | B36: =Inicio!$B$8 | C36: =Inicio!$B$9 | D36: =Inicio!$B$10 | E36: =Inicio!$B$11 | F36: =Inicio!$B$12
A37: 0 | B37: =1/5 | C37: =1/5 | D37: =1/5 | E37: =1/5 | F37: =1/5
A38: 1 | B38: =SUMPRODUCT($B$20:$F$20,$B37:$F37)/SUMPRODUCT($B$25:$F$25,$B37:$F37) | C38: =SUMPRODUCT($B$21:$F$21,$B37:$F37)/SUMPRODUCT($B$25:$F$25,$B37:$F37) | D38: =SUMPRODUCT($B$22:$F$22,$B37:$F37)/SUMPRODUCT($B$25:$F$25,$B37:$F37) | E38: =SUMPRODUCT($B$23:$F$23,$B37:$F37)/SUMPRODUCT($B$25:$F$25,$B37:$F37) | F38: =SUMPRODUCT($B$24:$F$24,$B37:$F37)/SUMPRODUCT($B$25:$F$25,$B37:$F37)
A39: 2 | B39: =SUMPRODUCT($B$20:$F$20,$B38:$F38)/SUMPRODUCT($B$25:$F$25,$B38:$F38) | C39: =SUMPRODUCT($B$21:$F$21,$B38:$F38)/SUMPRODUCT($B$25:$F$25,$B38:$F38) | D39: =SUMPRODUCT($B$22:$F$22,$B38:$F38)/SUMPRODUCT($B$25:$F$25,$B38:$F38) | E39: =SUMPRODUCT($B$23:$F$23,$B38:$F38)/SUMPRODUCT($B$25:$F$25,$B38:$F38) | F39: =SUMPRODUCT($B$24:$F$24,$B38:$F38)/SUMPRODUCT($B$25:$F$25,$B38:$F38)
A40: 3 | B40: =SUMPRODUCT($B$20:$F$20,$B39:$F39)/SUMPRODUCT($B$25:$F$25,$B39:$F39) | C40: =SUMPRODUCT($B$21:$F$21,$B39:$F39)/SUMPRODUCT($B$25:$F$25,$B39:$F39) | D40: =SUMPRODUCT($B$22:$F$22,$B39:$F39)/SUMPRODUCT($B$25:$F$25,$B39:$F39) | E40: =SUMPRODUCT($B$23:$F$23,$B39:$F39)/SUMPRODUCT($B$25:$F$25,$B39:$F39) | F40: =SUMPRODUCT($B$24:$F$24,$B39:$F39)/SUMPRODUCT($B$25:$F$25,$B39:$F39)
A41: 4 | B41: =SUMPRODUCT($B$20:$F$20,$B40:$F40)/SUMPRODUCT($B$25:$F$25,$B40:$F40) | C41: =SUMPRODUCT($B$21:$F$21,$B40:$F40)/SUMPRODUCT($B$25:$F$25,$B40:$F40) | D41: =SUMPRODUCT($B$22:$F$22,$B40:$F40)/SUMPRODUCT($B$25:$F$25,$B40:$F40) | E41: =SUMPRODUCT($B$23:$F$23,$B40:$F40)/SUMPRODUCT($B$25:$F$25,$B40:$F40) | F41: =SUMPRODUCT($B$24:$F$24,$B40:$F40)/SUMPRODUCT($B$25:$F$25,$B40:$F40)
A42: 5 | B42: =SUMPRODUCT($B$20:$F$20,$B41:$F41)/SUMPRODUCT($B$25:$F$25,$B41:$F41) | C42: =SUMPRODUCT($B$21:$F$21,$B41:$F41)/SUMPRODUCT($B$25:$F$25,$B41:$F41) | D42: =SUMPRODUCT($B$22:$F$22,$B41:$F41)/SUMPRODUCT($B$25:$F$25,$B41:$F41) | E42: =SUMPRODUCT($B$23:$F$23,$B41:$F41)/SUMPRODUCT($B$25:$F$25,$B41:$F41) | F42: =SUMPRODUCT($B$24:$F$24,$B41:$F41)/SUMPRODUCT($B$25:$F$25,$B41:$F41)
A43: 6 | B43: =SUMPRODUCT($B$20:$F$20,$B42:$F42)/SUMPRODUCT($B$25:$F$25,$B42:$F42) | C43: =SUMPRODUCT($B$21:$F$21,$B42:$F42)/SUMPRODUCT($B$25:$F$25,$B42:$F42) | D43: =SUMPRODUCT($B$22:$F$22,$B42:$F42)/SUMPRODUCT($B$25:$F$25,$B42:$F42) | E43: =SUMPRODUCT($B$23:$F$23,$B42:$F42)/SUMPRODUCT($B$25:$F$25,$B42:$F42) | F43: =SUMPRODUCT($B$24:$F$24,$B42:$F42)/SUMPRODUCT($B$25:$F$25,$B42:$F42)
A44: 7 | B44: =SUMPRODUCT($B$20:$F$20,$B43:$F43)/SUMPRODUCT($B$25:$F$25,$B43:$F43) | C44: =SUMPRODUCT($B$21:$F$21,$B43:$F43)/SUMPRODUCT($B$25:$F$25,$B43:$F43) | D44: =SUMPRODUCT($B$22:$F$22,$B43:$F43)/SUMPRODUCT($B$25:$F$25,$B43:$F43) | E44: =SUMPRODUCT($B$23:$F$23,$B43:$F43)/SUMPRODUCT($B$25:$F$25,$B43:$F43) | F44: =SUMPRODUCT($B$24:$F$24,$B43:$F43)/SUMPRODUCT($B$25:$F$25,$B43:$F43)
A45: 8 | B45: =SUMPRODUCT($B$20:$F$20,$B44:$F44)/SUMPRODUCT($B$25:$F$25,$B44:$F44) | C45: =SUMPRODUCT($B$21:$F$21,$B44:$F44)/SUMPRODUCT($B$25:$F$25,$B44:$F44) | D45: =SUMPRODUCT($B$22:$F$22,$B44:$F44)/SUMPRODUCT($B$25:$F$25,$B44:$F44) | E45: =SUMPRODUCT($B$23:$F$23,$B44:$F44)/SUMPRODUCT($B$25:$F$25,$B44:$F44) | F45: =SUMPRODUCT($B$24:$F$24,$B44:$F44)/SUMPRODUCT($B$25:$F$25,$B44:$F44)
...

Sheet Pertinencia
A1: ="Comparación por pares de las ALTERNATIVAS respecto al criterio: "&Inicio!$B$8
A2: Elija en 'Prefiere' cuál es más importante (Izquierda / Derecha / Igual) y en 'Valor' cuánto más (1 a 9, escala de Saaty). Edite solo las celdas amarillas.
A3: Escala: 1 igual · 3 moderada · 5 fuerte · 7 muy fuerte · 9 extrema (2, 4, 6, 8 intermedios).
A5: 1. Juicios de comparación por pares
A6: N° | B6: Izquierda | C6: Derecha | D6: Prefiere | E6: Valor (1-9) | F6: a(i,j) | G6: Lectura
A7: 1 | B7: =Inicio!$A$16&": "&Inicio!$B$16 | C7: =Inicio!$A$17&": "&Inicio!$B$17 | D7: Izquierda | E7: 2 | F7: =IF(D7="Izquierda",E7,IF(D7="Derecha",1/E7,1)) | G7: =IF(D7="Igual",B7&" = "&C7,IF(D7="Izquierda",B7&" > "&C7&" (x"&E7&")",C7&" > "&B7&" (x"&E7&")"))
A8: 2 | B8: =Inicio!$A$16&": "&Inicio!$B$16 | C8: =Inicio!$A$18&": "&Inicio!$B$18 | D8: Derecha | E8: 3 | F8: =IF(D8="Izquierda",E8,IF(D8="Derecha",1/E8,1)) | G8: =IF(D8="Igual",B8&" = "&C8,IF(D8="Izquierda",B8&" > "&C8&" (x"&E8&")",C8&" > "&B8&" (x"&E8&")"))
A9: 3 | B9: =Inicio!$A$17&": "&Inicio!$B$17 | C9: =Inicio!$A$18&": "&Inicio!$B$18 | D9: Derecha | E9: 5 | F9: =IF(D9="Izquierda",E9,IF(D9="Derecha",1/E9,1)) | G9: =IF(D9="Igual",B9&" = "&C9,IF(D9="Izquierda",B9&" > "&C9&" (x"&E9&")",C9&" > "&B9&" (x"&E9&")"))
A11: 2. Matriz de comparación y prioridades
B12: =Inicio!$A$16 | C12: =Inicio!$A$17 | D12: =Inicio!$A$18 | E12: Prioridad | F12: Posición
A13: =Inicio!$A$16 | B13: 1 | C13: =F7 | D13: =F8 | E13: =B53 | F13: =RANK(E13,$E$13:$E$15)
A14: =Inicio!$A$17 | B14: =1/C13 | C14: 1 | D14: =F9 | E14: =C53 | F14: =RANK(E14,$E$13:$E$15)
A15: =Inicio!$A$18 | B15: =1/D13 | C15: =1/D14 | D15: 1 | E15: =D53 | F15: =RANK(E15,$E$13:$E$15)
A16: Suma columna | B16: =SUM(B13:B15) | C16: =SUM(C13:C15) | D16: =SUM(D13:D15)
A18: Consistencia
A19: λ máx | B19: =SUMPRODUCT($B$16:$D$16,$B$53:$D$53)
A20: CI | B20: =(B19-3)/(3-1)
A21: RI | B21: {=INDEX(Inicio!$B$22:$B$26,3)}
A22: CR | B22: =IF(B21=0,0,B20/B21)
A23: Estado | B23: =IF(B22<0.1,"OK (CR < 10 %)","REVISAR: CR ≥ 10 %")
A26: 3. Cálculo del vector propio (método de las potencias, 25 iteraciones)
A27: Iteración | B27: =Inicio!$A$16 | C27: =Inicio!$A$17 | D27: =Inicio!$A$18
A28: 0 | B28: =1/3 | C28: =1/3 | D28: =1/3
A29: 1 | B29: =SUMPRODUCT($B$13:$D$13,$B28:$D28)/SUMPRODUCT($B$16:$D$16,$B28:$D28) | C29: =SUMPRODUCT($B$14:$D$14,$B28:$D28)/SUMPRODUCT($B$16:$D$16,$B28:$D28) | D29: =SUMPRODUCT($B$15:$D$15,$B28:$D28)/SUMPRODUCT($B$16:$D$16,$B28:$D28)
A30: 2 | B30: =SUMPRODUCT($B$13:$D$13,$B29:$D29)/SUMPRODUCT($B$16:$D$16,$B29:$D29) | C30: =SUMPRODUCT($B$14:$D$14,$B29:$D29)/SUMPRODUCT($B$16:$D$16,$B29:$D29) | D30: =SUMPRODUCT($B$15:$D$15,$B29:$D29)/SUMPRODUCT($B$16:$D$16,$B29:$D29)
A31: 3 | B31: =SUMPRODUCT($B$13:$D$13,$B30:$D30)/SUMPRODUCT($B$16:$D$16,$B30:$D30) | C31: =SUMPRODUCT($B$14:$D$14,$B30:$D30)/SUMPRODUCT($B$16:$D$16,$B30:$D30) | D31: =SUMPRODUCT($B$15:$D$15,$B30:$D30)/SUMPRODUCT($B$16:$D$16,$B30:$D30)
A32: 4 | B32: =SUMPRODUCT($B$13:$D$13,$B31:$D31)/SUMPRODUCT($B$16:$D$16,$B31:$D31) | C32: =SUMPRODUCT($B$14:$D$14,$B31:$D31)/SUMPRODUCT($B$16:$D$16,$B31:$D31) | D32: =SUMPRODUCT($B$15:$D$15,$B31:$D31)/SUMPRODUCT($B$16:$D$16,$B31:$D31)
A33: 5 | B33: =SUMPRODUCT($B$13:$D$13,$B32:$D32)/SUMPRODUCT($B$16:$D$16,$B32:$D32) | C33: =SUMPRODUCT($B$14:$D$14,$B32:$D32)/SUMPRODUCT($B$16:$D$16,$B32:$D32) | D33: =SUMPRODUCT($B$15:$D$15,$B32:$D32)/SUMPRODUCT($B$16:$D$16,$B32:$D32)
A34: 6 | B34: =SUMPRODUCT($B$13:$D$13,$B33:$D33)/SUMPRODUCT($B$16:$D$16,$B33:$D33) | C34: =SUMPRODUCT($B$14:$D$14,$B33:$D33)/SUMPRODUCT($B$16:$D$16,$B33:$D33) | D34: =SUMPRODUCT($B$15:$D$15,$B33:$D33)/SUMPRODUCT($B$16:$D$16,$B33:$D33)
A35: 7 | B35: =SUMPRODUCT($B$13:$D$13,$B34:$D34)/SUMPRODUCT($B$16:$D$16,$B34:$D34) | C35: =SUMPRODUCT($B$14:$D$14,$B34:$D34)/SUMPRODUCT($B$16:$D$16,$B34:$D34) | D35: =SUMPRODUCT($B$15:$D$15,$B34:$D34)/SUMPRODUCT($B$16:$D$16,$B34:$D34)
A36: 8 | B36: =SUMPRODUCT($B$13:$D$13,$B35:$D35)/SUMPRODUCT($B$16:$D$16,$B35:$D35) | C36: =SUMPRODUCT($B$14:$D$14,$B35:$D35)/SUMPRODUCT($B$16:$D$16,$B35:$D35) | D36: =SUMPRODUCT($B$15:$D$15,$B35:$D35)/SUMPRODUCT($B$16:$D$16,$B35:$D35)
A37: 9 | B37: =SUMPRODUCT($B$13:$D$13,$B36:$D36)/SUMPRODUCT($B$16:$D$16,$B36:$D36) | C37: =SUMPRODUCT($B$14:$D$14,$B36:$D36)/SUMPRODUCT($B$16:$D$16,$B36:$D36) | D37: =SUMPRODUCT($B$15:$D$15,$B36:$D36)/SUMPRODUCT($B$16:$D$16,$B36:$D36)
A38: 10 | B38: =SUMPRODUCT($B$13:$D$13,$B37:$D37)/SUMPRODUCT($B$16:$D$16,$B37:$D37) | C38: =SUMPRODUCT($B$14:$D$14,$B37:$D37)/SUMPRODUCT($B$16:$D$16,$B37:$D37) | D38: =SUMPRODUCT($B$15:$D$15,$B37:$D37)/SUMPRODUCT($B$16:$D$16,$B37:$D37)
A39: 11 | B39: =SUMPRODUCT($B$13:$D$13,$B38:$D38)/SUMPRODUCT($B$16:$D$16,$B38:$D38) | C39: =SUMPRODUCT($B$14:$D$14,$B38:$D38)/SUMPRODUCT($B$16:$D$16,$B38:$D38) | D39: =SUMPRODUCT($B$15:$D$15,$B38:$D38)/SUMPRODUCT($B$16:$D$16,$B38:$D38)
A40: 12 | B40: =SUMPRODUCT($B$13:$D$13,$B39:$D39)/SUMPRODUCT($B$16:$D$16,$B39:$D39) | C40: =SUMPRODUCT($B$14:$D$14,$B39:$D39)/SUMPRODUCT($B$16:$D$16,$B39:$D39) | D40: =SUMPRODUCT($B$15:$D$15,$B39:$D39)/SUMPRODUCT($B$16:$D$16,$B39:$D39)
... A53: 25 | B53: =SUMPRODUCT($B$13:$D$13,$B52:$D52)/SUMPRODUCT($B$16:$D$16,$B52:$D52) | C53: =SUMPRODUCT($B$14:$D$14,$B52:$D52)/SUMPRODUCT($B$16:$D$16,$B52:$D52) | D53: =SUMPRODUCT($B$15:$D$15,$B52:$D52)/SUMPRODUCT($B$16:$D$16,$B52:$D52)

Sheet Datos
A1: ="Comparación por pares de las ALTERNATIVAS respecto al criterio: "&Inicio!$B$9
A2: Elija en 'Prefiere' cuál es más importante (Izquierda / Derecha / Igual) y en 'Valor' cuánto más (1 a 9, escala de Saaty). Edite solo las celdas amarillas.
A3: Escala: 1 igual · 3 moderada · 5 fuerte · 7 muy fuerte · 9 extrema (2, 4, 6, 8 intermedios).
A5: 1. Juicios de comparación por pares
A6: N° | B6: Izquierda | C6: Derecha | D6: Prefiere | E6: Valor (1-9) | F6: a(i,j) | G6: Lectura
A7: 1 | B7: =Inicio!$A$16&": "&Inicio!$B$16 | C7: =Inicio!$A$17&": "&Inicio!$B$17 | D7: Izquierda | E7: 3 | F7: =IF(D7="Izquierda",E7,IF(D7="Derecha",1/E7,1)) | G7: =IF(D7="Igual",B7&" = "&C7,IF(D7="Izquierda",B7&" > "&C7&" (x"&E7&")",C7&" > "&B7&" (x"&E7&")"))
A8: 2 | B8: =Inicio!$A$16&": "&Inicio!$B$16 | C8: =Inicio!$A$18&": "&Inicio!$B$18 | D8: Igual | E8: 1 | F8: =IF(D8="Izquierda",E8,IF(D8="Derecha",1/E8,1)) | G8: =IF(D8="Igual",B8&" = "&C8,IF(D8="Izquierda",B8&" > "&C8&" (x"&E8&")",C8&" > "&B8&" (x"&E8&")"))
A9: 3 | B9: =Inicio!$A$17&": "&Inicio!$B$17 | C9: =Inicio!$A$18&": "&Inicio!$B$18 | D9: Derecha | E9: 3 | F9: =IF(D9="Izquierda",E9,IF(D9="Derecha",1/E9,1)) | G9: =IF(D9="Igual",B9&" = "&C9,IF(D9="Izquierda",B9&" > "&C9&" (x"&E9&")",C9&" > "&B9&" (x"&E9&")"))
A11: 2. Matriz de comparación y prioridades
B12: =Inicio!$A$16 | C12: =Inicio!$A$17 | D12: =Inicio!$A$18 | E12: Prioridad | F12: Posición
A13: =Inicio!$A$16 | B13: 1 | C13: =F7 | D13: =F8 | E13: =B53 | F13: =RANK(E13,$E$13:$E$15)
A14: =Inicio!$A$17 | B14: =1/C13 | C14: 1 | D14: =F9 | E14: =C53 | F14: =RANK(E14,$E$13:$E$15)
A15: =Inicio!$A$18 | B15: =1/D13 | C15: =1/D14 | D15: 1 | E15: =D53 | F15: =RANK(E15,$E$13:$E$15)
A16: Suma columna | B16: =SUM(B13:B15) | C16: =SUM(C13:C15) | D16: =SUM(D13:D15)
A18: Consistencia
A19: λ máx | B19: =SUMPRODUCT($B$16:$D$16,$B$53:$D$53)
A20: CI | B20: =(B19-3)/(3-1)
A21: RI | B21: {=INDEX(Inicio!$B$22:$B$26,3)}
A22: CR | B22: =IF(B21=0,0,B20/B21)
A23: Estado | B23: =IF(B22<0.1,"OK (CR < 10 %)","REVISAR: CR ≥ 10 %")
A26: 3. Cálculo del vector propio (método de las potencias, 25 iteraciones)
A27: Iteración | B27: =Inicio!$A$16 | C27: =Inicio!$A$17 | D27: =Inicio!$A$18
A28: 0 | B28: =1/3 | C28: =1/3 | D28: =1/3
A29: 1 | B29: =SUMPRODUCT($B$13:$D$13,$B28:$D28)/SUMPRODUCT($B$16:$D$16,$B28:$D28) | C29: =SUMPRODUCT($B$14:$D$14,$B28:$D28)/SUMPRODUCT($B$16:$D$16,$B28:$D28) | D29: =SUMPRODUCT($B$15:$D$15,$B28:$D28)/SUMPRODUCT($B$16:$D$16,$B28:$D28)
A30: 2 | B30: =SUMPRODUCT($B$13:$D$13,$B29:$D29)/SUMPRODUCT($B$16:$D$16,$B29:$D29) | C30: =SUMPRODUCT($B$14:$D$14,$B29:$D29)/SUMPRODUCT($B$16:$D$16,$B29:$D29) | D30: =SUMPRODUCT($B$15:$D$15,$B29:$D29)/SUMPRODUCT($B$16:$D$16,$B29:$D29)
A31: 3 | B31: =SUMPRODUCT($B$13:$D$13,$B30:$D30)/SUMPRODUCT($B$16:$D$16,$B30:$D30) | C31: =SUMPRODUCT($B$14:$D$14,$B30:$D30)/SUMPRODUCT($B$16:$D$16,$B30:$D30) | D31: =SUMPRODUCT($B$15:$D$15,$B30:$D30)/SUMPRODUCT($B$16:$D$16,$B30:$D30)
A32: 4 | B32: =SUMPRODUCT($B$13:$D$13,$B31:$D31)/SUMPRODUCT($B$16:$D$16,$B31:$D31) | C32: =SUMPRODUCT($B$14:$D$14,$B31:$D31)/SUMPRODUCT($B$16:$D$16,$B31:$D31) | D32: =SUMPRODUCT($B$15:$D$15,$B31:$D31)/SUMPRODUCT($B$16:$D$16,$B31:$D31)
A33: 5 | B33: =SUMPRODUCT($B$13:$D$13,$B32:$D32)/SUMPRODUCT($B$16:$D$16,$B32:$D32) | C33: =SUMPRODUCT($B$14:$D$14,$B32:$D32)/SUMPRODUCT($B$16:$D$16,$B32:$D32) | D33: =SUMPRODUCT($B$15:$D$15,$B32:$D32)/SUMPRODUCT($B$16:$D$16,$B32:$D32)
A34: 6 | B34: =SUMPRODUCT($B$13:$D$13,$B33:$D33)/SUMPRODUCT($B$16:$D$16,$B33:$D33) | C34: =SUMPRODUCT($B$14:$D$14,$B33:$D33)/SUMPRODUCT($B$16:$D$16,$B33:$D33) | D34: =SUMPRODUCT($B$15:$D$15,$B33:$D33)/SUMPRODUCT($B$16:$D$16,$B33:$D33)
A35: 7 | B35: =SUMPRODUCT($B$13:$D$13,$B34:$D34)/SUMPRODUCT($B$16:$D$16,$B34:$D34) | C35: =SUMPRODUCT($B$14:$D$14,$B34:$D34)/SUMPRODUCT($B$16:$D$16,$B34:$D34) | D35: =SUMPRODUCT($B$15:$D$15,$B34:$D34)/SUMPRODUCT($B$16:$D$16,$B34:$D34)
A36: 8 | B36: =SUMPRODUCT($B$13:$D$13,$B35:$D35)/SUMPRODUCT($B$16:$D$16,$B35:$D35) | C36: =SUMPRODUCT($B$14:$D$14,$B35:$D35)/SUMPRODUCT($B$16:$D$16,$B35:$D35) | D36: =SUMPRODUCT($B$15:$D$15,$B35:$D35)/SUMPRODUCT($B$16:$D$16,$B35:$D35)
A37: 9 | B37: =SUMPRODUCT($B$13:$D$13,$B36:$D36)/SUMPRODUCT($B$16:$D$16,$B36:$D36) | C37: =SUMPRODUCT($B$14:$D$14,$B36:$D36)/SUMPRODUCT($B$16:$D$16,$B36:$D36) | D37: =SUMPRODUCT($B$15:$D$15,$B36:$D36)/SUMPRODUCT($B$16:$D$16,$B36:$D36)
A38: 10 | B38: =SUMPRODUCT($B$13:$D$13,$B37:$D37)/SUMPRODUCT($B$16:$D$16,$B37:$D37) | C38: =SUMPRODUCT($B$14:$D$14,$B37:$D37)/SUMPRODUCT($B$16:$D$16,$B37:$D37) | D38: =SUMPRODUCT($B$15:$D$15,$B37:$D37)/SUMPRODUCT($B$16:$D$16,$B37:$D37)
A39: 11 | B39: =SUMPRODUCT($B$13:$D$13,$B38:$D38)/SUMPRODUCT($B$16:$D$16,$B38:$D38) | C39: =SUMPRODUCT($B$14:$D$14,$B38:$D38)/SUMPRODUCT($B$16:$D$16,$B38:$D38) | D39: =SUMPRODUCT($B$15:$D$15,$B38:$D38)/SUMPRODUCT($B$16:$D$16,$B38:$D38)
A40: 12 | B40: =SUMPRODUCT($B$13:$D$13,$B39:$D39)/SUMPRODUCT($B$16:$D$16,$B39:$D39) | C40: =SUMPRODUCT($B$14:$D$14,$B39:$D39)/SUMPRODUCT($B$16:$D$16,$B39:$D39) | D40: =SUMPRODUCT($B$15:$D$15,$B39:$D39)/SUMPRODUCT($B$16:$D$16,$B39:$D39)
... A53: 25 | B53: =SUMPRODUCT($B$13:$D$13,$B52:$D52)/SUMPRODUCT($B$16:$D$16,$B52:$D52) | C53: =SUMPRODUCT($B$14:$D$14,$B52:$D52)/SUMPRODUCT($B$16:$D$16,$B52:$D52) | D53: =SUMPRODUCT($B$15:$D$15,$B52:$D52)/SUMPRODUCT($B$16:$D$16,$B52:$D52)

Sheet Viabilidad
A1: ="Comparación por pares de las ALTERNATIVAS respecto al criterio: "&Inicio!$B$10
A2: Elija en 'Prefiere' cuál es más importante (Izquierda / Derecha / Igual) y en 'Valor' cuánto más (1 a 9, escala de Saaty). Edite solo las celdas amarillas.
A3: Escala: 1 igual · 3 moderada · 5 fuerte · 7 muy fuerte · 9 extrema (2, 4, 6, 8 intermedios).
A5: 1. Juicios de comparación por pares
A6: N° | B6: Izquierda | C6: Derecha | D6: Prefiere | E6: Valor (1-9) | F6: a(i,j) | G6: Lectura
A7: 1 | B7: =Inicio!$A$16&": "&Inicio!$B$16 | C7: =Inicio!$A$17&": "&Inicio!$B$17 | D7: Izquierda | E7: 4 | F7: =IF(D7="Izquierda",E7,IF(D7="Derecha",1/E7,1)) | G7: =IF(D7="Igual",B7&" = "&C7,IF(D7="Izquierda",B7&" > "&C7&" (x"&E7&")",C7&" > "&B7&" (x"&E7&")"))
A8: 2 | B8: =Inicio!$A$16&": "&Inicio!$B$16 | C8: =Inicio!$A$18&": "&Inicio!$B$18 | D8: Igual | E8: 1 | F8: =IF(D8="Izquierda",E8,IF(D8="Derecha",1/E8,1)) | G8: =IF(D8="Igual",B8&" = "&C8,IF(D8="Izquierda",B8&" > "&C8&" (x"&E8&")",C8&" > "&B8&" (x"&E8&")"))
A9: 3 | B9: =Inicio!$A$17&": "&Inicio!$B$17 | C9: =Inicio!$A$18&": "&Inicio!$B$18 | D9: Derecha | E9: 4 | F9: =IF(D9="Izquierda",E9,IF(D9="Derecha",1/E9,1)) | G9: =IF(D9="Igual",B9&" = "&C9,IF(D9="Izquierda",B9&" > "&C9&" (x"&E9&")",C9&" > "&B9&" (x"&E9&")"))
A11: 2. Matriz de comparación y prioridades
B12: =Inicio!$A$16 | C12: =Inicio!$A$17 | D12: =Inicio!$A$18 | E12: Prioridad | F12: Posición
A13: =Inicio!$A$16 | B13: 1 | C13: =F7 | D13: =F8 | E13: =B53 | F13: =RANK(E13,$E$13:$E$15)
A14: =Inicio!$A$17 | B14: =1/C13 | C14: 1 | D14: =F9 | E14: =C53 | F14: =RANK(E14,$E$13:$E$15)
A15: =Inicio!$A$18 | B15: =1/D13 | C15: =1/D14 | D15: 1 | E15: =D53 | F15: =RANK(E15,$E$13:$E$15)
A16: Suma columna | B16: =SUM(B13:B15) | C16: =SUM(C13:C15) | D16: =SUM(D13:D15)
A18: Consistencia
A19: λ máx | B19: =SUMPRODUCT($B$16:$D$16,$B$53:$D$53)
A20: CI | B20: =(B19-3)/(3-1)
A21: RI | B21: {=INDEX(Inicio!$B$22:$B$26,3)}
A22: CR | B22: =IF(B21=0,0,B20/B21)
A23: Estado | B23: =IF(B22<0.1,"OK (CR < 10 %)","REVISAR: CR ≥ 10 %")
A26: 3. Cálculo del vector propio (método de las potencias, 25 iteraciones)
A27: Iteración | B27: =Inicio!$A$16 | C27: =Inicio!$A$17 | D27: =Inicio!$A$18
A28: 0 | B28: =1/3 | C28: =1/3 | D28: =1/3
A29: 1 | B29: =SUMPRODUCT($B$13:$D$13,$B28:$D28)/SUMPRODUCT($B$16:$D$16,$B28:$D28) | C29: =SUMPRODUCT($B$14:$D$14,$B28:$D28)/SUMPRODUCT($B$16:$D$16,$B28:$D28) | D29: =SUMPRODUCT($B$15:$D$15,$B28:$D28)/SUMPRODUCT($B$16:$D$16,$B28:$D28)
A30: 2 | B30: =SUMPRODUCT($B$13:$D$13,$B29:$D29)/SUMPRODUCT($B$16:$D$16,$B29:$D29) | C30: =SUMPRODUCT($B$14:$D$14,$B29:$D29)/SUMPRODUCT($B$16:$D$16,$B29:$D29) | D30: =SUMPRODUCT($B$15:$D$15,$B29:$D29)/SUMPRODUCT($B$16:$D$16,$B29:$D29)
A31: 3 | B31: =SUMPRODUCT($B$13:$D$13,$B30:$D30)/SUMPRODUCT($B$16:$D$16,$B30:$D30) | C31: =SUMPRODUCT($B$14:$D$14,$B30:$D30)/SUMPRODUCT($B$16:$D$16,$B30:$D30) | D31: =SUMPRODUCT($B$15:$D$15,$B30:$D30)/SUMPRODUCT($B$16:$D$16,$B30:$D30)
A32: 4 | B32: =SUMPRODUCT($B$13:$D$13,$B31:$D31)/SUMPRODUCT($B$16:$D$16,$B31:$D31) | C32: =SUMPRODUCT($B$14:$D$14,$B31:$D31)/SUMPRODUCT($B$16:$D$16,$B31:$D31) | D32: =SUMPRODUCT($B$15:$D$15,$B31:$D31)/SUMPRODUCT($B$16:$D$16,$B31:$D31)
A33: 5 | B33: =SUMPRODUCT($B$13:$D$13,$B32:$D32)/SUMPRODUCT($B$16:$D$16,$B32:$D32) | C33: =SUMPRODUCT($B$14:$D$14,$B32:$D32)/SUMPRODUCT($B$16:$D$16,$B32:$D32) | D33: =SUMPRODUCT($B$15:$D$15,$B32:$D32)/SUMPRODUCT($B$16:$D$16,$B32:$D32)
A34: 6 | B34: =SUMPRODUCT($B$13:$D$13,$B33:$D33)/SUMPRODUCT($B$16:$D$16,$B33:$D33) | C34: =SUMPRODUCT($B$14:$D$14,$B33:$D33)/SUMPRODUCT($B$16:$D$16,$B33:$D33) | D34: =SUMPRODUCT($B$15:$D$15,$B33:$D33)/SUMPRODUCT($B$16:$D$16,$B33:$D33)
A35: 7 | B35: =SUMPRODUCT($B$13:$D$13,$B34:$D34)/SUMPRODUCT($B$16:$D$16,$B34:$D34) | C35: =SUMPRODUCT($B$14:$D$14,$B34:$D34)/SUMPRODUCT($B$16:$D$16,$B34:$D34) | D35: =SUMPRODUCT($B$15:$D$15,$B34:$D34)/SUMPRODUCT($B$16:$D$16,$B34:$D34)
A36: 8 | B36: =SUMPRODUCT($B$13:$D$13,$B35:$D35)/SUMPRODUCT($B$16:$D$16,$B35:$D35) | C36: =SUMPRODUCT($B$14:$D$14,$B35:$D35)/SUMPRODUCT($B$16:$D$16,$B35:$D35) | D36: =SUMPRODUCT($B$15:$D$15,$B35:$D35)/SUMPRODUCT($B$16:$D$16,$B35:$D35)
A37: 9 | B37: =SUMPRODUCT($B$13:$D$13,$B36:$D36)/SUMPRODUCT($B$16:$D$16,$B36:$D36) | C37: =SUMPRODUCT($B$14:$D$14,$B36:$D36)/SUMPRODUCT($B$16:$D$16,$B36:$D36) | D37: =SUMPRODUCT($B$15:$D$15,$B36:$D36)/SUMPRODUCT($B$16:$D$16,$B36:$D36)
A38: 10 | B38: =SUMPRODUCT($B$13:$D$13,$B37:$D37)/SUMPRODUCT($B$16:$D$16,$B37:$D37) | C38: =SUMPRODUCT($B$14:$D$14,$B37:$D37)/SUMPRODUCT($B$16:$D$16,$B37:$D37) | D38: =SUMPRODUCT($B$15:$D$15,$B37:$D37)/SUMPRODUCT($B$16:$D$16,$B37:$D37)
A39: 11 | B39: =SUMPRODUCT($B$13:$D$13,$B38:$D38)/SUMPRODUCT($B$16:$D$16,$B38:$D38) | C39: =SUMPRODUCT($B$14:$D$14,$B38:$D38)/SUMPRODUCT($B$16:$D$16,$B38:$D38) | D39: =SUMPRODUCT($B$15:$D$15,$B38:$D38)/SUMPRODUCT($B$16:$D$16,$B38:$D38)
A40: 12 | B40: =SUMPRODUCT($B$13:$D$13,$B39:$D39)/SUMPRODUCT($B$16:$D$16,$B39:$D39) | C40: =SUMPRODUCT($B$14:$D$14,$B39:$D39)/SUMPRODUCT($B$16:$D$16,$B39:$D39) | D40: =SUMPRODUCT($B$15:$D$15,$B39:$D39)/SUMPRODUCT($B$16:$D$16,$B39:$D39)
... A53: 25 | B53: =SUMPRODUCT($B$13:$D$13,$B52:$D52)/SUMPRODUCT($B$16:$D$16,$B52:$D52) | C53: =SUMPRODUCT($B$14:$D$14,$B52:$D52)/SUMPRODUCT($B$16:$D$16,$B52:$D52) | D53: =SUMPRODUCT($B$15:$D$15,$B52:$D52)/SUMPRODUCT($B$16:$D$16,$B52:$D52)

Sheet Impacto
A1: ="Comparación por pares de las ALTERNATIVAS respecto al criterio: "&Inicio!$B$11
A2: Elija en 'Prefiere' cuál es más importante (Izquierda / Derecha / Igual) y en 'Valor' cuánto más (1 a 9, escala de Saaty). Edite solo las celdas amarillas.
A3: Escala: 1 igual · 3 moderada · 5 fuerte · 7 muy fuerte · 9 extrema (2, 4, 6, 8 intermedios).
A5: 1. Juicios de comparación por pares
A6: N° | B6: Izquierda | C6: Derecha | D6: Prefiere | E6: Valor (1-9) | F6: a(i,j) | G6: Lectura
A7: 1 | B7: =Inicio!$A$16&": "&Inicio!$B$16 | C7: =Inicio!$A$17&": "&Inicio!$B$17 | D7: Derecha | E7: 4 | F7: =IF(D7="Izquierda",E7,IF(D7="Derecha",1/E7,1)) | G7: =IF(D7="Igual",B7&" = "&C7,IF(D7="Izquierda",B7&" > "&C7&" (x"&E7&")",C7&" > "&B7&" (x"&E7&")"))
A8: 2 | B8: =Inicio!$A$16&": "&Inicio!$B$16 | C8: =Inicio!$A$18&": "&Inicio!$B$18 | D8: Derecha | E8: 4 | F8: =IF(D8="Izquierda",E8,IF(D8="Derecha",1/E8,1)) | G8: =IF(D8="Igual",B8&" = "&C8,IF(D8="Izquierda",B8&" > "&C8&" (x"&E8&")",C8&" > "&B8&" (x"&E8&")"))
A9: 3 | B9: =Inicio!$A$17&": "&Inicio!$B$17 | C9: =Inicio!$A$18&": "&Inicio!$B$18 | D9: Igual | E9: 1 | F9: =IF(D9="Izquierda",E9,IF(D9="Derecha",1/E9,1)) | G9: =IF(D9="Igual",B9&" = "&C9,IF(D9="Izquierda",B9&" > "&C9&" (x"&E9&")",C9&" > "&B9&" (x"&E9&")"))
A11: 2. Matriz de comparación y prioridades
B12: =Inicio!$A$16 | C12: =Inicio!$A$17 | D12: =Inicio!$A$18 | E12: Prioridad | F12: Posición
A13: =Inicio!$A$16 | B13: 1 | C13: =F7 | D13: =F8 | E13: =B53 | F13: =RANK(E13,$E$13:$E$15)
A14: =Inicio!$A$17 | B14: =1/C13 | C14: 1 | D14: =F9 | E14: =C53 | F14: =RANK(E14,$E$13:$E$15)
A15: =Inicio!$A$18 | B15: =1/D13 | C15: =1/D14 | D15: 1 | E15: =D53 | F15: =RANK(E15,$E$13:$E$15)
A16: Suma columna | B16: =SUM(B13:B15) | C16: =SUM(C13:C15) | D16: =SUM(D13:D15)
A18: Consistencia
A19: λ máx | B19: =SUMPRODUCT($B$16:$D$16,$B$53:$D$53)
A20: CI | B20: =(B19-3)/(3-1)
A21: RI | B21: {=INDEX(Inicio!$B$22:$B$26,3)}
A22: CR | B22: =IF(B21=0,0,B20/B21)
A23: Estado | B23: =IF(B22<0.1,"OK (CR < 10 %)","REVISAR: CR ≥ 10 %")
A26: 3. Cálculo del vector propio (método de las potencias, 25 iteraciones)
A27: Iteración | B27: =Inicio!$A$16 | C27: =Inicio!$A$17 | D27: =Inicio!$A$18
A28: 0 | B28: =1/3 | C28: =1/3 | D28: =1/3
A29: 1 | B29: =SUMPRODUCT($B$13:$D$13,$B28:$D28)/SUMPRODUCT($B$16:$D$16,$B28:$D28) | C29: =SUMPRODUCT($B$14:$D$14,$B28:$D28)/SUMPRODUCT($B$16:$D$16,$B28:$D28) | D29: =SUMPRODUCT($B$15:$D$15,$B28:$D28)/SUMPRODUCT($B$16:$D$16,$B28:$D28)
A30: 2 | B30: =SUMPRODUCT($B$13:$D$13,$B29:$D29)/SUMPRODUCT($B$16:$D$16,$B29:$D29) | C30: =SUMPRODUCT($B$14:$D$14,$B29:$D29)/SUMPRODUCT($B$16:$D$16,$B29:$D29) | D30: =SUMPRODUCT($B$15:$D$15,$B29:$D29)/SUMPRODUCT($B$16:$D$16,$B29:$D29)
A31: 3 | B31: =SUMPRODUCT($B$13:$D$13,$B30:$D30)/SUMPRODUCT($B$16:$D$16,$B30:$D30) | C31: =SUMPRODUCT($B$14:$D$14,$B30:$D30)/SUMPRODUCT($B$16:$D$16,$B30:$D30) | D31: =SUMPRODUCT($B$15:$D$15,$B30:$D30)/SUMPRODUCT($B$16:$D$16,$B30:$D30)
A32: 4 | B32: =SUMPRODUCT($B$13:$D$13,$B31:$D31)/SUMPRODUCT($B$16:$D$16,$B31:$D31) | C32: =SUMPRODUCT($B$14:$D$14,$B31:$D31)/SUMPRODUCT($B$16:$D$16,$B31:$D31) | D32: =SUMPRODUCT($B$15:$D$15,$B31:$D31)/SUMPRODUCT($B$16:$D$16,$B31:$D31)
A33: 5 | B33: =SUMPRODUCT($B$13:$D$13,$B32:$D32)/SUMPRODUCT($B$16:$D$16,$B32:$D32) | C33: =SUMPRODUCT($B$14:$D$14,$B32:$D32)/SUMPRODUCT($B$16:$D$16,$B32:$D32) | D33: =SUMPRODUCT($B$15:$D$15,$B32:$D32)/SUMPRODUCT($B$16:$D$16,$B32:$D32)
A34: 6 | B34: =SUMPRODUCT($B$13:$D$13,$B33:$D33)/SUMPRODUCT($B$16:$D$16,$B33:$D33) | C34: =SUMPRODUCT($B$14:$D$14,$B33:$D33)/SUMPRODUCT($B$16:$D$16,$B33:$D33) | D34: =SUMPRODUCT($B$15:$D$15,$B33:$D33)/SUMPRODUCT($B$16:$D$16,$B33:$D33)
A35: 7 | B35: =SUMPRODUCT($B$13:$D$13,$B34:$D34)/SUMPRODUCT($B$16:$D$16,$B34:$D34) | C35: =SUMPRODUCT($B$14:$D$14,$B34:$D34)/SUMPRODUCT($B$16:$D$16,$B34:$D34) | D35: =SUMPRODUCT($B$15:$D$15,$B34:$D34)/SUMPRODUCT($B$16:$D$16,$B34:$D34)
A36: 8 | B36: =SUMPRODUCT($B$13:$D$13,$B35:$D35)/SUMPRODUCT($B$16:$D$16,$B35:$D35) | C36: =SUMPRODUCT($B$14:$D$14,$B35:$D35)/SUMPRODUCT($B$16:$D$16,$B35:$D35) | D36: =SUMPRODUCT($B$15:$D$15,$B35:$D35)/SUMPRODUCT($B$16:$D$16,$B35:$D35)
A37: 9 | B37: =SUMPRODUCT($B$13:$D$13,$B36:$D36)/SUMPRODUCT($B$16:$D$16,$B36:$D36) | C37: =SUMPRODUCT($B$14:$D$14,$B36:$D36)/SUMPRODUCT($B$16:$D$16,$B36:$D36) | D37: =SUMPRODUCT($B$15:$D$15,$B36:$D36)/SUMPRODUCT($B$16:$D$16,$B36:$D36)
A38: 10 | B38: =SUMPRODUCT($B$13:$D$13,$B37:$D37)/SUMPRODUCT($B$16:$D$16,$B37:$D37) | C38: =SUMPRODUCT($B$14:$D$14,$B37:$D37)/SUMPRODUCT($B$16:$D$16,$B37:$D37) | D38: =SUMPRODUCT($B$15:$D$15,$B37:$D37)/SUMPRODUCT($B$16:$D$16,$B37:$D37)
A39: 11 | B39: =SUMPRODUCT($B$13:$D$13,$B38:$D38)/SUMPRODUCT($B$16:$D$16,$B38:$D38) | C39: =SUMPRODUCT($B$14:$D$14,$B38:$D38)/SUMPRODUCT($B$16:$D$16,$B38:$D38) | D39: =SUMPRODUCT($B$15:$D$15,$B38:$D38)/SUMPRODUCT($B$16:$D$16,$B38:$D38)
A40: 12 | B40: =SUMPRODUCT($B$13:$D$13,$B39:$D39)/SUMPRODUCT($B$16:$D$16,$B39:$D39) | C40: =SUMPRODUCT($B$14:$D$14,$B39:$D39)/SUMPRODUCT($B$16:$D$16,$B39:$D39) | D40: =SUMPRODUCT($B$15:$D$15,$B39:$D39)/SUMPRODUCT($B$16:$D$16,$B39:$D39)
... A53: 25 | B53: =SUMPRODUCT($B$13:$D$13,$B52:$D52)/SUMPRODUCT($B$16:$D$16,$B52:$D52) | C53: =SUMPRODUCT($B$14:$D$14,$B52:$D52)/SUMPRODUCT($B$16:$D$16,$B52:$D52) | D53: =SUMPRODUCT($B$15:$D$15,$B52:$D52)/SUMPRODUCT($B$16:$D$16,$B52:$D52)

Sheet Caso_real
A1: ="Comparación por pares de las ALTERNATIVAS respecto al criterio: "&Inicio!$B$12
A2: Elija en 'Prefiere' cuál es más importante (Izquierda / Derecha / Igual) y en 'Valor' cuánto más (1 a 9, escala de Saaty). Edite solo las celdas amarillas.
A3: Escala: 1 igual · 3 moderada · 5 fuerte · 7 muy fuerte · 9 extrema (2, 4, 6, 8 intermedios).
A5: 1. Juicios de comparación por pares
A6: N° | B6: Izquierda | C6: Derecha | D6: Prefiere | E6: Valor (1-9) | F6: a(i,j) | G6: Lectura
A7: 1 | B7: =Inicio!$A$16&": "&Inicio!$B$16 | C7: =Inicio!$A$17&": "&Inicio!$B$17 | D7: Izquierda | E7: 3 | F7: =IF(D7="Izquierda",E7,IF(D7="Derecha",1/E7,1)) | G7: =IF(D7="Igual",B7&" = "&C7,IF(D7="Izquierda",B7&" > "&C7&" (x"&E7&")",C7&" > "&B7&" (x"&E7&")"))
A8: 2 | B8: =Inicio!$A$16&": "&Inicio!$B$16 | C8: =Inicio!$A$18&": "&Inicio!$B$18 | D8: Igual | E8: 1 | F8: =IF(D8="Izquierda",E8,IF(D8="Derecha",1/E8,1)) | G8: =IF(D8="Igual",B8&" = "&C8,IF(D8="Izquierda",B8&" > "&C8&" (x"&E8&")",C8&" > "&B8&" (x"&E8&")"))
A9: 3 | B9: =Inicio!$A$17&": "&Inicio!$B$17 | C9: =Inicio!$A$18&": "&Inicio!$B$18 | D9: Derecha | E9: 3 | F9: =IF(D9="Izquierda",E9,IF(D9="Derecha",1/E9,1)) | G9: =IF(D9="Igual",B9&" = "&C9,IF(D9="Izquierda",B9&" > "&C9&" (x"&E9&")",C9&" > "&B9&" (x"&E9&")"))
A11: 2. Matriz de comparación y prioridades
B12: =Inicio!$A$16 | C12: =Inicio!$A$17 | D12: =Inicio!$A$18 | E12: Prioridad | F12: Posición
A13: =Inicio!$A$16 | B13: 1 | C13: =F7 | D13: =F8 | E13: =B53 | F13: =RANK(E13,$E$13:$E$15)
A14: =Inicio!$A$17 | B14: =1/C13 | C14: 1 | D14: =F9 | E14: =C53 | F14: =RANK(E14,$E$13:$E$15)
A15: =Inicio!$A$18 | B15: =1/D13 | C15: =1/D14 | D15: 1 | E15: =D53 | F15: =RANK(E15,$E$13:$E$15)
A16: Suma columna | B16: =SUM(B13:B15) | C16: =SUM(C13:C15) | D16: =SUM(D13:D15)
A18: Consistencia
A19: λ máx | B19: =SUMPRODUCT($B$16:$D$16,$B$53:$D$53)
A20: CI | B20: =(B19-3)/(3-1)
A21: RI | B21: {=INDEX(Inicio!$B$22:$B$26,3)}
A22: CR | B22: =IF(B21=0,0,B20/B21)
A23: Estado | B23: =IF(B22<0.1,"OK (CR < 10 %)","REVISAR: CR ≥ 10 %")
A26: 3. Cálculo del vector propio (método de las potencias, 25 iteraciones)
A27: Iteración | B27: =Inicio!$A$16 | C27: =Inicio!$A$17 | D27: =Inicio!$A$18
A28: 0 | B28: =1/3 | C28: =1/3 | D28: =1/3
A29: 1 | B29: =SUMPRODUCT($B$13:$D$13,$B28:$D28)/SUMPRODUCT($B$16:$D$16,$B28:$D28) | C29: =SUMPRODUCT($B$14:$D$14,$B28:$D28)/SUMPRODUCT($B$16:$D$16,$B28:$D28) | D29: =SUMPRODUCT($B$15:$D$15,$B28:$D28)/SUMPRODUCT($B$16:$D$16,$B28:$D28)
A30: 2 | B30: =SUMPRODUCT($B$13:$D$13,$B29:$D29)/SUMPRODUCT($B$16:$D$16,$B29:$D29) | C30: =SUMPRODUCT($B$14:$D$14,$B29:$D29)/SUMPRODUCT($B$16:$D$16,$B29:$D29) | D30: =SUMPRODUCT($B$15:$D$15,$B29:$D29)/SUMPRODUCT($B$16:$D$16,$B29:$D29)
A31: 3 | B31: =SUMPRODUCT($B$13:$D$13,$B30:$D30)/SUMPRODUCT($B$16:$D$16,$B30:$D30) | C31: =SUMPRODUCT($B$14:$D$14,$B30:$D30)/SUMPRODUCT($B$16:$D$16,$B30:$D30) | D31: =SUMPRODUCT($B$15:$D$15,$B30:$D30)/SUMPRODUCT($B$16:$D$16,$B30:$D30)
A32: 4 | B32: =SUMPRODUCT($B$13:$D$13,$B31:$D31)/SUMPRODUCT($B$16:$D$16,$B31:$D31) | C32: =SUMPRODUCT($B$14:$D$14,$B31:$D31)/SUMPRODUCT($B$16:$D$16,$B31:$D31) | D32: =SUMPRODUCT($B$15:$D$15,$B31:$D31)/SUMPRODUCT($B$16:$D$16,$B31:$D31)
A33: 5 | B33: =SUMPRODUCT($B$13:$D$13,$B32:$D32)/SUMPRODUCT($B$16:$D$16,$B32:$D32) | C33: =SUMPRODUCT($B$14:$D$14,$B32:$D32)/SUMPRODUCT($B$16:$D$16,$B32:$D32) | D33: =SUMPRODUCT($B$15:$D$15,$B32:$D32)/SUMPRODUCT($B$16:$D$16,$B32:$D32)
A34: 6 | B34: =SUMPRODUCT($B$13:$D$13,$B33:$D33)/SUMPRODUCT($B$16:$D$16,$B33:$D33) | C34: =SUMPRODUCT($B$14:$D$14,$B33:$D33)/SUMPRODUCT($B$16:$D$16,$B33:$D33) | D34: =SUMPRODUCT($B$15:$D$15,$B33:$D33)/SUMPRODUCT($B$16:$D$16,$B33:$D33)
A35: 7 | B35: =SUMPRODUCT($B$13:$D$13,$B34:$D34)/SUMPRODUCT($B$16:$D$16,$B34:$D34) | C35: =SUMPRODUCT($B$14:$D$14,$B34:$D34)/SUMPRODUCT($B$16:$D$16,$B34:$D34) | D35: =SUMPRODUCT($B$15:$D$15,$B34:$D34)/SUMPRODUCT($B$16:$D$16,$B34:$D34)
A36: 8 | B36: =SUMPRODUCT($B$13:$D$13,$B35:$D35)/SUMPRODUCT($B$16:$D$16,$B35:$D35) | C36: =SUMPRODUCT($B$14:$D$14,$B35:$D35)/SUMPRODUCT($B$16:$D$16,$B35:$D35) | D36: =SUMPRODUCT($B$15:$D$15,$B35:$D35)/SUMPRODUCT($B$16:$D$16,$B35:$D35)
A37: 9 | B37: =SUMPRODUCT($B$13:$D$13,$B36:$D36)/SUMPRODUCT($B$16:$D$16,$B36:$D36) | C37: =SUMPRODUCT($B$14:$D$14,$B36:$D36)/SUMPRODUCT($B$16:$D$16,$B36:$D36) | D37: =SUMPRODUCT($B$15:$D$15,$B36:$D36)/SUMPRODUCT($B$16:$D$16,$B36:$D36)
A38: 10 | B38: =SUMPRODUCT($B$13:$D$13,$B37:$D37)/SUMPRODUCT($B$16:$D$16,$B37:$D37) | C38: =SUMPRODUCT($B$14:$D$14,$B37:$D37)/SUMPRODUCT($B$16:$D$16,$B37:$D37) | D38: =SUMPRODUCT($B$15:$D$15,$B37:$D37)/SUMPRODUCT($B$16:$D$16,$B37:$D37)
A39: 11 | B39: =SUMPRODUCT($B$13:$D$13,$B38:$D38)/SUMPRODUCT($B$16:$D$16,$B38:$D38) | C39: =SUMPRODUCT($B$14:$D$14,$B38:$D38)/SUMPRODUCT($B$16:$D$16,$B38:$D38) | D39: =SUMPRODUCT($B$15:$D$15,$B38:$D38)/SUMPRODUCT($B$16:$D$16,$B38:$D38)
A40: 12 | B40: =SUMPRODUCT($B$13:$D$13,$B39:$D39)/SUMPRODUCT($B$16:$D$16,$B39:$D39) | C40: =SUMPRODUCT($B$14:$D$14,$B39:$D39)/SUMPRODUCT($B$16:$D$16,$B39:$D39) | D40: =SUMPRODUCT($B$15:$D$15,$B39:$D39)/SUMPRODUCT($B$16:$D$16,$B39:$D39)
... A53: 25 | B53: =SUMPRODUCT($B$13:$D$13,$B52:$D52)/SUMPRODUCT($B$16:$D$16,$B52:$D52) | C53: =SUMPRODUCT($B$14:$D$14,$B52:$D52)/SUMPRODUCT($B$16:$D$16,$B52:$D52) | D53: =SUMPRODUCT($B$15:$D$15,$B52:$D52)/SUMPRODUCT($B$16:$D$16,$B52:$D52)

Sheet Resultados
A1: Resultados del AHP
A2: Todo se calcula con fórmulas a partir de las hojas de comparación.
A4: 1. Pesos de los criterios
A5: Criterio | B5: Peso | C5: Posición
A6: =Inicio!$B$8 | B6: =Criterios!G20 | C6: =RANK(B6,$B$6:$B$10)
A7: =Inicio!$B$9 | B7: =Criterios!G21 | C7: =RANK(B7,$B$6:$B$10)
A8: =Inicio!$B$10 | B8: =Criterios!G22 | C8: =RANK(B8,$B$6:$B$10)
A9: =Inicio!$B$11 | B9: =Criterios!G23 | C9: =RANK(B9,$B$6:$B$10)
A10: =Inicio!$B$12 | B10: =Criterios!G24 | C10: =RANK(B10,$B$6:$B$10)
A11: Suma / CR de la matriz de criterios | B11: =SUM(B6:B10) | C11: =Criterios!B31 | D11: =Criterios!B32
A13: 2. Prioridades locales de las alternativas por criterio
B14: =Inicio!$B$8 | C14: =Inicio!$B$9 | D14: =Inicio!$B$10 | E14: =Inicio!$B$11 | F14: =Inicio!$B$12 | G14: Puntaje global
A15: Peso del criterio | B15: =$B$6 | C15: =$B$7 | D15: =$B$8 | E15: =$B$9 | F15: =$B$10 | G15: =SUM(B15:F15)
A16: =Inicio!$A$16&": "&Inicio!$B$16 | B16: =Pertinencia!E13 | C16: =Datos!E13 | D16: =Viabilidad!E13 | E16: =Impacto!E13 | F16: =Caso_real!E13 | G16: =SUMPRODUCT($B$15:$F$15,B16:F16)
A17: =Inicio!$A$17&": "&Inicio!$B$17 | B17: =Pertinencia!E14 | C17: =Datos!E14 | D17: =Viabilidad!E14 | E17: =Impacto!E14 | F17: =Caso_real!E14 | G17: =SUMPRODUCT($B$15:$F$15,B17:F17)
A18: =Inicio!$A$18&": "&Inicio!$B$18 | B18: =Pertinencia!E15 | C18: =Datos!E15 | D18: =Viabilidad!E15 | E18: =Impacto!E15 | F18: =Caso_real!E15 | G18: =SUMPRODUCT($B$15:$F$15,B18:F18)
A19: CR de la matriz | B19: =Pertinencia!B22 | C19: =Datos!B22 | D19: =Viabilidad!B22 | E19: =Impacto!B22 | F19: =Caso_real!B22 | G19: =IF(AND(MAX(B19:F19)<0.1,C11<0.1),"OK","REVISAR")
A21: 3. Ranking final
A22: Tema | B22: Puntaje global | C22: Posición
A23: =Inicio!$A$16&": "&Inicio!$B$16 | B23: =G16 | C23: =RANK(B23,$B$23:$B$25)
A24: =Inicio!$A$17&": "&Inicio!$B$17 | B24: =G17 | C24: =RANK(B24,$B$23:$B$25)
A25: =Inicio!$A$18&": "&Inicio!$B$18 | B25: =G18 | C25: =RANK(B25,$B$23:$B$25)
A26: Total | B26: =SUM(B23:B25)
A27: Tema recomendado | B27: {=INDEX(A23:A25,MATCH(MAX(B23:B25),B23:B25,0))}
A29: 4. Aporte de cada criterio al puntaje global (peso × prioridad local)
A30: Tema | B30: =Inicio!$B$8 | C30: =Inicio!$B$9 | D30: =Inicio!$B$10 | E30: =Inicio!$B$11 | F30: =Inicio!$B$12 | G30: Total
A31: =Inicio!$A$16&": "&Inicio!$B$16 | B31: =B$15*B16 | C31: =C$15*C16 | D31: =D$15*D16 | E31: =E$15*E16 | F31: =F$15*F16 | G31: =SUM(B31:F31)
A32: =Inicio!$A$17&": "&Inicio!$B$17 | B32: =B$15*B17 | C32: =C$15*C17 | D32: =D$15*D17 | E32: =E$15*E17 | F32: =F$15*F17 | G32: =SUM(B32:F32)
A33: =Inicio!$A$18&": "&Inicio!$B$18 | B33: =B$15*B18 | C33: =C$15*C18 | D33: =D$15*D18 | E33: =E$15*E18 | F33: =F$15*F18 | G33: =SUM(B33:F33)
A35: 5. Jerarquía de decisión (equivalente a la tabla de AHP-OS)
A36: Criterio | B36: Peso criterio | C36: Alternativa | D36: Prioridad local | E36: Prioridad global
A37: =Inicio!$B$8 | B37: =B$15 | C37: =Inicio!$A$16 | D37: =B16 | E37: =B37*D37
A38: =Inicio!$B$8 | B38: =B$15 | C38: =Inicio!$A$17 | D38: =B17 | E38: =B38*D38
A39: =Inicio!$B$8 | B39: =B$15 | C39: =Inicio!$A$18 | D39: =B18 | E39: =B39*D39
A40: =Inicio!$B$9 | B40: =C$15 | C40: =Inicio!$A$16 | D40: =C16 | E40: =B40*D40
A41: =Inicio!$B$9 | B41: =C$15 | C41: =Inicio!$A$17 | D41: =C17 | E41: =B41*D41
A42: =Inicio!$B$9 | B42: =C$15 | C42: =Inicio!$A$18 | D42: =C18 | E42: =B42*D42
A43: =Inicio!$B$10 | B43: =D$15 | C43: =Inicio!$A$16 | D43: =D16 | E43: =B43*D43
A44: =Inicio!$B$10 | B44: =D$15 | C44: =Inicio!$A$17 | D44: =D17 | E44: =B44*D44
A45: =Inicio!$B$10 | B45: =D$15 | C45: =Inicio!$A$18 | D45: =D18 | E45: =B45*D45
...

Sheet Sensibilidad
A1: Análisis de sensibilidad
A2: Pregunta: ¿el tema ganador sigue siendo el mismo si los pesos de los criterios cambian? Si el ganador se mantiene en todos los escenarios razonables, la decisión es robusta.
A4: 1. Escenarios de ponderación
A5: Escenario | B5: =Inicio!$B$8 | C5: =Inicio!$B$9 | D5: =Inicio!$B$10 | E5: =Inicio!$B$11 | F5: =Inicio!$B$12 | G5: Suma | H5: ="Puntaje "&Inicio!$A$16 | I5: ="Puntaje "&Inicio!$A$17 | J5: ="Puntaje "&Inicio!$A$18 | K5: Ganador | L5: Margen 1º-2º
A6: Base (AHP) | B6: =Resultados!B15 | C6: =Resultados!C15 | D6: =Resultados!D15 | E6: =Resultados!E15 | F6: =Resultados!F15 | G6: =SUM(B6:F6) | H6: =SUMPRODUCT($B6:$F6,Resultados!$B$16:$F$16)/$G6 | I6: =SUMPRODUCT($B6:$F6,Resultados!$B$17:$F$17)/$G6 | J6: =SUMPRODUCT($B6:$F6,Resultados!$B$18:$F$18)/$G6 | K6: {=INDEX(Inicio!$A$16:$A$18,MATCH(MAX(H6:J6),H6:J6,0))} | L6: =LARGE(H6:J6,1)-LARGE(H6:J6,2)
A7: Viabilidad baja | B7: 0.25 | C7: 0.25 | D7: 0.3 | E7: 0.1 | F7: 0.1 | G7: =SUM(B7:F7) | H7: =SUMPRODUCT($B7:$F7,Resultados!$B$16:$F$16)/$G7 | I7: =SUMPRODUCT($B7:$F7,Resultados!$B$17:$F$17)/$G7 | J7: =SUMPRODUCT($B7:$F7,Resultados!$B$18:$F$18)/$G7 | K7: {=INDEX(Inicio!$A$16:$A$18,MATCH(MAX(H7:J7),H7:J7,0))} | L7: =LARGE(H7:J7,1)-LARGE(H7:J7,2)
A8: Pesos iguales | B8: 0.2 | C8: 0.2 | D8: 0.2 | E8: 0.2 | F8: 0.2 | G8: =SUM(B8:F8) | H8: =SUMPRODUCT($B8:$F8,Resultados!$B$16:$F$16)/$G8 | I8: =SUMPRODUCT($B8:$F8,Resultados!$B$17:$F$17)/$G8 | J8: =SUMPRODUCT($B8:$F8,Resultados!$B$18:$F$18)/$G8 | K8: {=INDEX(Inicio!$A$16:$A$18,MATCH(MAX(H8:J8),H8:J8,0))} | L8: =LARGE(H8:J8,1)-LARGE(H8:J8,2)
A9: Impacto alto | B9: 0.15 | C9: 0.15 | D9: 0.3 | E9: 0.3 | F9: 0.1 | G9: =SUM(B9:F9) | H9: =SUMPRODUCT($B9:$F9,Resultados!$B$16:$F$16)/$G9 | I9: =SUMPRODUCT($B9:$F9,Resultados!$B$17:$F$17)/$G9 | J9: =SUMPRODUCT($B9:$F9,Resultados!$B$18:$F$18)/$G9 | K9: {=INDEX(Inicio!$A$16:$A$18,MATCH(MAX(H9:J9),H9:J9,0))} | L9: =LARGE(H9:J9,1)-LARGE(H9:J9,2)
A10: Caso real alto | B10: 0.15 | C10: 0.15 | D10: 0.3 | E10: 0.1 | F10: 0.3 | G10: =SUM(B10:F10) | H10: =SUMPRODUCT($B10:$F10,Resultados!$B$16:$F$16)/$G10 | I10: =SUMPRODUCT($B10:$F10,Resultados!$B$17:$F$17)/$G10 | J10: =SUMPRODUCT($B10:$F10,Resultados!$B$18:$F$18)/$G10 | K10: {=INDEX(Inicio!$A$16:$A$18,MATCH(MAX(H10:J10),H10:J10,0))} | L10: =LARGE(H10:J10,1)-LARGE(H10:J10,2)
A11: Sin Viabilidad | B11: 0.3 | C11: 0.3 | D11: 0 | E11: 0.2 | F11: 0.2 | G11: =SUM(B11:F11) | H11: =SUMPRODUCT($B11:$F11,Resultados!$B$16:$F$16)/$G11 | I11: =SUMPRODUCT($B11:$F11,Resultados!$B$17:$F$17)/$G11 | J11: =SUMPRODUCT($B11:$F11,Resultados!$B$18:$F$18)/$G11 | K11: {=INDEX(Inicio!$A$16:$A$18,MATCH(MAX(H11:J11),H11:J11,0))} | L11: =LARGE(H11:J11,1)-LARGE(H11:J11,2)
A12: ¿El ganador cambia en algún escenario? | F12: =IF(COUNTIF(K6:K11,K6)=ROWS(K6:K11),"NO: decisión robusta","SÍ: revisar")
A35: 2. Peso crítico: ¿cuánto debe pesar un criterio para que otro tema supere al ganador?
A36: Se varía el peso de un criterio de 0 % a 100 % y los demás se reajustan proporcionalmente. 'No cambia' = ningún peso entre 0 % y 100 % hace que ese rival supere al ganador.
A37: Ganador base (posición) | B37: =MATCH(MAX(Resultados!$G$16:$G$18),Resultados!$G$16:$G$18,0) | C37: {=INDEX(Inicio!$A$16:$A$18,B37)}
A39: Criterio | B39: Peso base | C39: ="Rival "&Inicio!$A$16 | D39: ="Rival "&Inicio!$A$17 | E39: ="Rival "&Inicio!$A$18 | F39: ¿Robusto?
A40: =Inicio!$B$8 | B40: =Resultados!B15 | C40: =IF(1=$B$37,"—",IF(B49=B56,"No cambia",IF(AND((-B56/(B49-B56))>=0,(-B56/(B49-B56))<0.999999),(-B56/(B49-B56)),"No cambia"))) | D40: =IF(2=$B$37,"—",IF(C49=C56,"No cambia",IF(AND((-C56/(C49-C56))>=0,(-C56/(C49-C56))<0.999999),(-C56/(C49-C56)),"No cambia"))) | E40: =IF(3=$B$37,"—",IF(D49=D56,"No cambia",IF(AND((-D56/(D49-D56))>=0,(-D56/(D49-D56))<0.999999),(-D56/(D49-D56)),"No cambia"))) | F40: =IF(COUNT(C40:E40)=0,"Robusto","Cambia si llega al peso crítico")
A41: =Inicio!$B$9 | B41: =Resultados!C15 | C41: =IF(1=$B$37,"—",IF(B50=B57,"No cambia",IF(AND((-B57/(B50-B57))>=0,(-B57/(B50-B57))<0.999999),(-B57/(B50-B57)),"No cambia"))) | D41: =IF(2=$B$37,"—",IF(C50=C57,"No cambia",IF(AND((-C57/(C50-C57))>=0,(-C57/(C50-C57))<0.999999),(-C57/(C50-C57)),"No cambia"))) | E41: =IF(3=$B$37,"—",IF(D50=D57,"No cambia",IF(AND((-D57/(D50-D57))>=0,(-D57/(D50-D57))<0.999999),(-D57/(D50-D57)),"No cambia"))) | F41: =IF(COUNT(C41:E41)=0,"Robusto","Cambia si llega al peso crítico")
A42: =Inicio!$B$10 | B42: =Resultados!D15 | C42: =IF(1=$B$37,"—",IF(B51=B58,"No cambia",IF(AND((-B58/(B51-B58))>=0,(-B58/(B51-B58))<0.999999),(-B58/(B51-B58)),"No cambia"))) | D42: =IF(2=$B$37,"—",IF(C51=C58,"No cambia",IF(AND((-C58/(C51-C58))>=0,(-C58/(C51-C58))<0.999999),(-C58/(C51-C58)),"No cambia"))) | E42: =IF(3=$B$37,"—",IF(D51=D58,"No cambia",IF(AND((-D58/(D51-D58))>=0,(-D58/(D51-D58))<0.999999),(-D58/(D51-D58)),"No cambia"))) | F42: =IF(COUNT(C42:E42)=0,"Robusto","Cambia si llega al peso crítico")
A43: =Inicio!$B$11 | B43: =Resultados!E15 | C43: =IF(1=$B$37,"—",IF(B52=B59,"No cambia",IF(AND((-B59/(B52-B59))>=0,(-B59/(B52-B59))<0.999999),(-B59/(B52-B59)),"No cambia"))) | D43: =IF(2=$B$37,"—",IF(C52=C59,"No cambia",IF(AND((-C59/(C52-C59))>=0,(-C59/(C52-C59))<0.999999),(-C59/(C52-C59)),"No cambia"))) | E43: =IF(3=$B$37,"—",IF(D52=D59,"No cambia",IF(AND((-D59/(D52-D59))>=0,(-D59/(D52-D59))<0.999999),(-D59/(D52-D59)),"No cambia"))) | F43: =IF(COUNT(C43:E43)=0,"Robusto","Cambia si llega al peso crítico")
A44: =Inicio!$B$12 | B44: =Resultados!F15 | C44: =IF(1=$B$37,"—",IF(B53=B60,"No cambia",IF(AND((-B60/(B53-B60))>=0,(-B60/(B53-B60))<0.999999),(-B60/(B53-B60)),"No cambia"))) | D44: =IF(2=$B$37,"—",IF(C53=C60,"No cambia",IF(AND((-C60/(C53-C60))>=0,(-C60/(C53-C60))<0.999999),(-C60/(C53-C60)),"No cambia"))) | E44: =IF(3=$B$37,"—",IF(D53=D60,"No cambia",IF(AND((-D60/(D53-D60))>=0,(-D60/(D53-D60))<0.999999),(-D60/(D53-D60)),"No cambia"))) | F44: =IF(COUNT(C44:E44)=0,"Robusto","Cambia si llega al peso crítico")
A47: Cálculos auxiliares (d1 = ventaja del ganador si el criterio pesa 100 %; d0 = ventaja si pesa 0 %)
A48: d1 por criterio | B48: ="vs "&Inicio!$A$16 | C48: ="vs "&Inicio!$A$17 | D48: ="vs "&Inicio!$A$18
A49: =Inicio!$B$8 | B49: {=INDEX(Resultados!$B$16:$F$18,$B$37,1)-INDEX(Resultados!$B$16:$F$18,1,1)} | C49: {=INDEX(Resultados!$B$16:$F$18,$B$37,1)-INDEX(Resultados!$B$16:$F$18,2,1)} | D49: {=INDEX(Resultados!$B$16:$F$18,$B$37,1)-INDEX(Resultados!$B$16:$F$18,3,1)}
A50: =Inicio!$B$9 | B50: {=INDEX(Resultados!$B$16:$F$18,$B$37,2)-INDEX(Resultados!$B$16:$F$18,1,2)} | C50: {=INDEX(Resultados!$B$16:$F$18,$B$37,2)-INDEX(Resultados!$B$16:$F$18,2,2)} | D50: {=INDEX(Resultados!$B$16:$F$18,$B$37,2)-INDEX(Resultados!$B$16:$F$18,3,2)}
A51: =Inicio!$B$10 | B51: {=INDEX(Resultados!$B$16:$F$18,$B$37,3)-INDEX(Resultados!$B$16:$F$18,1,3)} | C51: {=INDEX(Resultados!$B$16:$F$18,$B$37,3)-INDEX(Resultados!$B$16:$F$18,2,3)} | D51: {=INDEX(Resultados!$B$16:$F$18,$B$37,3)-INDEX(Resultados!$B$16:$F$18,3,3)}
A52: =Inicio!$B$11 | B52: {=INDEX(Resultados!$B$16:$F$18,$B$37,4)-INDEX(Resultados!$B$16:$F$18,1,4)} | C52: {=INDEX(Resultados!$B$16:$F$18,$B$37,4)-INDEX(Resultados!$B$16:$F$18,2,4)} | D52: {=INDEX(Resultados!$B$16:$F$18,$B$37,4)-INDEX(Resultados!$B$16:$F$18,3,4)}
A53: =Inicio!$B$12 | B53: {=INDEX(Resultados!$B$16:$F$18,$B$37,5)-INDEX(Resultados!$B$16:$F$18,1,5)} | C53: {=INDEX(Resultados!$B$16:$F$18,$B$37,5)-INDEX(Resultados!$B$16:$F$18,2,5)} | D53: {=INDEX(Resultados!$B$16:$F$18,$B$37,5)-INDEX(Resultados!$B$16:$F$18,3,5)}
A55: d0 por criterio | B55: ="vs "&Inicio!$A$16 | C55: ="vs "&Inicio!$A$17 | D55: ="vs "&Inicio!$A$18
A56: =Inicio!$B$8 | B56: {=IFERROR(((INDEX(Resultados!$G$16:$G$18,$B$37)-INDEX(Resultados!$B$15:$F$15,1)*INDEX(Resultados!$B$16:$F$18,$B$37,1))-(INDEX(Resultados!$G$16:$G$18,1)-INDEX(Resultados!$B$15:$F$15,1)*INDEX(Resultados!$B$16:$F$18,1,1)))/(1-INDEX(Resultados!$B$15:$F$15,1)),0)} | C56: {=IFERROR(((INDEX(Resultados!$G$16:$G$18,$B$37)-INDEX(Resultados!$B$15:$F$15,1)*INDEX(Resultados!$B$16:$F$18,$B$37,1))-(INDEX(Resultados!$G$16:$G$18,2)-INDEX(Resultados!$B$15:$F$15,1)*INDEX(Resultados!$B$16:$F$18,2,1)))/(1-INDEX(Resultados!$B$15:$F$15,1)),0)} | D56: {=IFERROR(((INDEX(Resultados!$G$16:$G$18,$B$37)-INDEX(Resultados!$B$15:$F$15,1)*INDEX(Resultados!$B$16:$F$18,$B$37,1))-(INDEX(Resultados!$G$16:$G$18,3)-INDEX(Resultados!$B$15:$F$15,1)*INDEX(Resultados!$B$16:$F$18,3,1)))/(1-INDEX(Resultados!$B$15:$F$15,1)),0)}
A57: =Inicio!$B$9 | B57: {=IFERROR(((INDEX(Resultados!$G$16:$G$18,$B$37)-INDEX(Resultados!$B$15:$F$15,2)*INDEX(Resultados!$B$16:$F$18,$B$37,2))-(INDEX(Resultados!$G$16:$G$18,1)-INDEX(Resultados!$B$15:$F$15,2)*INDEX(Resultados!$B$16:$F$18,1,2)))/(1-INDEX(Resultados!$B$15:$F$15,2)),0)} | C57: {=IFERROR(((INDEX(Resultados!$G$16:$G$18,$B$37)-INDEX(Resultados!$B$15:$F$15,2)*INDEX(Resultados!$B$16:$F$18,$B$37,2))-(INDEX(Resultados!$G$16:$G$18,2)-INDEX(Resultados!$B$15:$F$15,2)*INDEX(Resultados!$B$16:$F$18,2,2)))/(1-INDEX(Resultados!$B$15:$F$15,2)),0)} | D57: {=IFERROR(((INDEX(Resultados!$G$16:$G$18,$B$37)-INDEX(Resultados!$B$15:$F$15,2)*INDEX(Resultados!$B$16:$F$18,$B$37,2))-(INDEX(Resultados!$G$16:$G$18,3)-INDEX(Resultados!$B$15:$F$15,2)*INDEX(Resultados!$B$16:$F$18,3,2)))/(1-INDEX(Resultados!$B$15:$F$15,2)),0)}
A58: =Inicio!$B$10 | B58: {=IFERROR(((INDEX(Resultados!$G$16:$G$18,$B$37)-INDEX(Resultados!$B$15:$F$15,3)*INDEX(Resultados!$B$16:$F$18,$B$37,3))-(INDEX(Resultados!$G$16:$G$18,1)-INDEX(Resultados!$B$15:$F$15,3)*INDEX(Resultados!$B$16:$F$18,1,3)))/(1-INDEX(Resultados!$B$15:$F$15,3)),0)} | C58: {=IFERROR(((INDEX(Resultados!$G$16:$G$18,$B$37)-INDEX(Resultados!$B$15:$F$15,3)*INDEX(Resultados!$B$16:$F$18,$B$37,3))-(INDEX(Resultados!$G$16:$G$18,2)-INDEX(Resultados!$B$15:$F$15,3)*INDEX(Resultados!$B$16:$F$18,2,3)))/(1-INDEX(Resultados!$B$15:$F$15,3)),0)} | D58: {=IFERROR(((INDEX(Resultados!$G$16:$G$18,$B$37)-INDEX(Resultados!$B$15:$F$15,3)*INDEX(Resultados!$B$16:$F$18,$B$37,3))-(INDEX(Resultados!$G$16:$G$18,3)-INDEX(Resultados!$B$15:$F$15,3)*INDEX(Resultados!$B$16:$F$18,3,3)))/(1-INDEX(Resultados!$B$15:$F$15,3)),0)}
A59: =Inicio!$B$11 | B59: {=IFERROR(((INDEX(Resultados!$G$16:$G$18,$B$37)-INDEX(Resultados!$B$15:$F$15,4)*INDEX(Resultados!$B$16:$F$18,$B$37,4))-(INDEX(Resultados!$G$16:$G$18,1)-INDEX(Resultados!$B$15:$F$15,4)*INDEX(Resultados!$B$16:$F$18,1,4)))/(1-INDEX(Resultados!$B$15:$F$15,4)),0)} | C59: {=IFERROR(((INDEX(Resultados!$G$16:$G$18,$B$37)-INDEX(Resultados!$B$15:$F$15,4)*INDEX(Resultados!$B$16:$F$18,$B$37,4))-(INDEX(Resultados!$G$16:$G$18,2)-INDEX(Resultados!$B$15:$F$15,4)*INDEX(Resultados!$B$16:$F$18,2,4)))/(1-INDEX(Resultados!$B$15:$F$15,4)),0)} | D59: {=IFERROR(((INDEX(Resultados!$G$16:$G$18,$B$37)-INDEX(Resultados!$B$15:$F$15,4)*INDEX(Resultados!$B$16:$F$18,$B$37,4))-(INDEX(Resultados!$G$16:$G$18,3)-INDEX(Resultados!$B$15:$F$15,4)*INDEX(Resultados!$B$16:$F$18,3,4)))/(1-INDEX(Resultados!$B$15:$F$15,4)),0)}
A60: =Inicio!$B$12 | B60: {=IFERROR(((INDEX(Resultados!$G$16:$G$18,$B$37)-INDEX(Resultados!$B$15:$F$15,5)*INDEX(Resultados!$B$16:$F$18,$B$37,5))-(INDEX(Resultados!$G$16:$G$18,1)-INDEX(Resultados!$B$15:$F$15,5)*INDEX(Resultados!$B$16:$F$18,1,5)))/(1-INDEX(Resultados!$B$15:$F$15,5)),0)} | C60: {=IFERROR(((INDEX(Resultados!$G$16:$G$18,$B$37)-INDEX(Resultados!$B$15:$F$15,5)*INDEX(Resultados!$B$16:$F$18,$B$37,5))-(INDEX(Resultados!$G$16:$G$18,2)-INDEX(Resultados!$B$15:$F$15,5)*INDEX(Resultados!$B$16:$F$18,2,5)))/(1-INDEX(Resultados!$B$15:$F$15,5)),0)} | D60: {=IFERROR(((INDEX(Resultados!$G$16:$G$18,$B$37)-INDEX(Resultados!$B$15:$F$15,5)*INDEX(Resultados!$B$16:$F$18,$B$37,5))-(INDEX(Resultados!$G$16:$G$18,3)-INDEX(Resultados!$B$15:$F$15,5)*INDEX(Resultados!$B$16:$F$18,3,5)))/(1-INDEX(Resultados!$B$15:$F$15,5)),0)}

Sheet Barrido
A1: Barrido de un criterio de 0 % a 100 %
A2: Para cada criterio se varía su peso y los demás se reparten el resto en proporción a sus pesos base. Celda roja en 'Ganador' = el ganador base es superado.
A4: ="Criterio: "&Inicio!$B$8&" (peso base: "&TEXT(Resultados!B15,"0.0%")&")"
A5: Peso del criterio | B5: ="Puntaje "&Inicio!$A$16 | C5: ="Puntaje "&Inicio!$A$17 | D5: ="Puntaje "&Inicio!$A$18 | E5: Ganador
A6: 0 | B6: =$A6*Resultados!$B$16+(1-$A6)*(Resultados!$G$16-Resultados!$B$15*Resultados!$B$16)/(1-Resultados!$B$15) | C6: =$A6*Resultados!$B$17+(1-$A6)*(Resultados!$G$17-Resultados!$B$15*Resultados!$B$17)/(1-Resultados!$B$15) | D6: =$A6*Resultados!$B$18+(1-$A6)*(Resultados!$G$18-Resultados!$B$15*Resultados!$B$18)/(1-Resultados!$B$15) | E6: {=IF(INDEX(B6:D6,Sensibilidad!$B$37)>=MAX(B6:D6)-0.0000001,Sensibilidad!$C$37,INDEX(Inicio!$A$16:$A$18,MATCH(MAX(B6:D6),B6:D6,0)))}
A7: 0.05 | B7: =$A7*Resultados!$B$16+(1-$A7)*(Resultados!$G$16-Resultados!$B$15*Resultados!$B$16)/(1-Resultados!$B$15) | C7: =$A7*Resultados!$B$17+(1-$A7)*(Resultados!$G$17-Resultados!$B$15*Resultados!$B$17)/(1-Resultados!$B$15) | D7: =$A7*Resultados!$B$18+(1-$A7)*(Resultados!$G$18-Resultados!$B$15*Resultados!$B$18)/(1-Resultados!$B$15) | E7: {=IF(INDEX(B7:D7,Sensibilidad!$B$37)>=MAX(B7:D7)-0.0000001,Sensibilidad!$C$37,INDEX(Inicio!$A$16:$A$18,MATCH(MAX(B7:D7),B7:D7,0)))}
A8: 0.1 | B8: =$A8*Resultados!$B$16+(1-$A8)*(Resultados!$G$16-Resultados!$B$15*Resultados!$B$16)/(1-Resultados!$B$15) | C8: =$A8*Resultados!$B$17+(1-$A8)*(Resultados!$G$17-Resultados!$B$15*Resultados!$B$17)/(1-Resultados!$B$15) | D8: =$A8*Resultados!$B$18+(1-$A8)*(Resultados!$G$18-Resultados!$B$15*Resultados!$B$18)/(1-Resultados!$B$15) | E8: {=IF(INDEX(B8:D8,Sensibilidad!$B$37)>=MAX(B8:D8)-0.0000001,Sensibilidad!$C$37,INDEX(Inicio!$A$16:$A$18,MATCH(MAX(B8:D8),B8:D8,0)))}
A9: 0.15 | B9: =$A9*Resultados!$B$16+(1-$A9)*(Resultados!$G$16-Resultados!$B$15*Resultados!$B$16)/(1-Resultados!$B$15) | C9: =$A9*Resultados!$B$17+(1-$A9)*(Resultados!$G$17-Resultados!$B$15*Resultados!$B$17)/(1-Resultados!$B$15) | D9: =$A9*Resultados!$B$18+(1-$A9)*(Resultados!$G$18-Resultados!$B$15*Resultados!$B$18)/(1-Resultados!$B$15) | E9: {=IF(INDEX(B9:D9,Sensibilidad!$B$37)>=MAX(B9:D9)-0.0000001,Sensibilidad!$C$37,INDEX(Inicio!$A$16:$A$18,MATCH(MAX(B9:D9),B9:D9,0)))}
A10: 0.2 | B10: =$A10*Resultados!$B$16+(1-$A10)*(Resultados!$G$16-Resultados!$B$15*Resultados!$B$16)/(1-Resultados!$B$15) | C10: =$A10*Resultados!$B$17+(1-$A10)*(Resultados!$G$17-Resultados!$B$15*Resultados!$B$17)/(1-Resultados!$B$15) | D10: =$A10*Resultados!$B$18+(1-$A10)*(Resultados!$G$18-Resultados!$B$15*Resultados!$B$18)/(1-Resultados!$B$15) | E10: {=IF(INDEX(B10:D10,Sensibilidad!$B$37)>=MAX(B10:D10)-0.0000001,Sensibilidad!$C$37,INDEX(Inicio!$A$16:$A$18,MATCH(MAX(B10:D10),B10:D10,0)))}
A11: 0.25 | B11: =$A11*Resultados!$B$16+(1-$A11)*(Resultados!$G$16-Resultados!$B$15*Resultados!$B$16)/(1-Resultados!$B$15) | C11: =$A11*Resultados!$B$17+(1-$A11)*(Resultados!$G$17-Resultados!$B$15*Resultados!$B$17)/(1-Resultados!$B$15) | D11: =$A11*Resultados!$B$18+(1-$A11)*(Resultados!$G$18-Resultados!$B$15*Resultados!$B$18)/(1-Resultados!$B$15) | E11: {=IF(INDEX(B11:D11,Sensibilidad!$B$37)>=MAX(B11:D11)-0.0000001,Sensibilidad!$C$37,INDEX(Inicio!$A$16:$A$18,MATCH(MAX(B11:D11),B11:D11,0)))}
A12: 0.3 | B12: =$A12*Resultados!$B$16+(1-$A12)*(Resultados!$G$16-Resultados!$B$15*Resultados!$B$16)/(1-Resultados!$B$15) | C12: =$A12*Resultados!$B$17+(1-$A12)*(Resultados!$G$17-Resultados!$B$15*Resultados!$B$17)/(1-Resultados!$B$15) | D12: =$A12*Resultados!$B$18+(1-$A12)*(Resultados!$G$18-Resultados!$B$15*Resultados!$B$18)/(1-Resultados!$B$15) | E12: {=IF(INDEX(B12:D12,Sensibilidad!$B$37)>=MAX(B12:D12)-0.0000001,Sensibilidad!$C$37,INDEX(Inicio!$A$16:$A$18,MATCH(MAX(B12:D12),B12:D12,0)))}
A13: 0.35 | B13: =$A13*Resultados!$B$16+(1-$A13)*(Resultados!$G$16-Resultados!$B$15*Resultados!$B$16)/(1-Resultados!$B$15) | C13: =$A13*Resultados!$B$17+(1-$A13)*(Resultados!$G$17-Resultados!$B$15*Resultados!$B$17)/(1-Resultados!$B$15) | D13: =$A13*Resultados!$B$18+(1-$A13)*(Resultados!$G$18-Resultados!$B$15*Resultados!$B$18)/(1-Resultados!$B$15) | E13: {=IF(INDEX(B13:D13,Sensibilidad!$B$37)>=MAX(B13:D13)-0.0000001,Sensibilidad!$C$37,INDEX(Inicio!$A$16:$A$18,MATCH(MAX(B13:D13),B13:D13,0)))}
A14: 0.4 | B14: =$A14*Resultados!$B$16+(1-$A14)*(Resultados!$G$16-Resultados!$B$15*Resultados!$B$16)/(1-Resultados!$B$15) | C14: =$A14*Resultados!$B$17+(1-$A14)*(Resultados!$G$17-Resultados!$B$15*Resultados!$B$17)/(1-Resultados!$B$15) | D14: =$A14*Resultados!$B$18+(1-$A14)*(Resultados!$G$18-Resultados!$B$15*Resultados!$B$18)/(1-Resultados!$B$15) | E14: {=IF(INDEX(B14:D14,Sensibilidad!$B$37)>=MAX(B14:D14)-0.0000001,Sensibilidad!$C$37,INDEX(Inicio!$A$16:$A$18,MATCH(MAX(B14:D14),B14:D14,0)))}
A15: 0.45 | B15: =$A15*Resultados!$B$16+(1-$A15)*(Resultados!$G$16-Resultados!$B$15*Resultados!$B$16)/(1-Resultados!$B$15) | C15: =$A15*Resultados!$B$17+(1-$A15)*(Resultados!$G$17-Resultados!$B$15*Resultados!$B$17)/(1-Resultados!$B$15) | D15: =$A15*Resultados!$B$18+(1-$A15)*(Resultados!$G$18-Resultados!$B$15*Resultados!$B$18)/(1-Resultados!$B$15) | E15: {=IF(INDEX(B15:D15,Sensibilidad!$B$37)>=MAX(B15:D15)-0.0000001,Sensibilidad!$C$37,INDEX(Inicio!$A$16:$A$18,MATCH(MAX(B15:D15),B15:D15,0)))}
A16: 0.5 | B16: =$A16*Resultados!$B$16+(1-$A16)*(Resultados!$G$16-Resultados!$B$15*Resultados!$B$16)/(1-Resultados!$B$15) | C16: =$A16*Resultados!$B$17+(1-$A16)*(Resultados!$G$17-Resultados!$B$15*Resultados!$B$17)/(1-Resultados!$B$15) | D16: =$A16*Resultados!$B$18+(1-$A16)*(Resultados!$G$18-Resultados!$B$15*Resultados!$B$18)/(1-Resultados!$B$15) | E16: {=IF(INDEX(B16:D16,Sensibilidad!$B$37)>=MAX(B16:D16)-0.0000001,Sensibilidad!$C$37,INDEX(Inicio!$A$16:$A$18,MATCH(MAX(B16:D16),B16:D16,0)))}
A17: 0.55 | B17: =$A17*Resultados!$B$16+(1-$A17)*(Resultados!$G$16-Resultados!$B$15*Resultados!$B$16)/(1-Resultados!$B$15) | C17: =$A17*Resultados!$B$17+(1-$A17)*(Resultados!$G$17-Resultados!$B$15*Resultados!$B$17)/(1-Resultados!$B$15) | D17: =$A17*Resultados!$B$18+(1-$A17)*(Resultados!$G$18-Resultados!$B$15*Resultados!$B$18)/(1-Resultados!$B$15) | E17: {=IF(INDEX(B17:D17,Sensibilidad!$B$37)>=MAX(B17:D17)-0.0000001,Sensibilidad!$C$37,INDEX(Inicio!$A$16:$A$18,MATCH(MAX(B17:D17),B17:D17,0)))}
... A26: 1 | B26: =$A26*Resultados!$B$16+(1-$A26)*(Resultados!$G$16-Resultados!$B$15*Resultados!$B$16)/(1-Resultados!$B$15) | C26: =$A26*Resultados!$B$17+(1-$A26)*(Resultados!$G$17-Resultados!$B$15*Resultados!$B$17)/(1-Resultados!$B$15) | D26: =$A26*Resultados!$B$18+(1-$A26)*(Resultados!$G$18-Resultados!$B$15*Resultados!$B$18)/(1-Resultados!$B$15) | E26: {=IF(INDEX(B26:D26,Sensibilidad!$B$37)>=MAX(B26:D26)-0.0000001,Sensibilidad!$C$37,INDEX(Inicio!$A$16:$A$18,MATCH(MAX(B26:D26),B26:D26,0)))}
A30: ="Criterio: "&Inicio!$B$9&" (peso base: "&TEXT(Resultados!C15,"0.0%")&")"
A31: Peso del criterio | B31: ="Puntaje "&Inicio!$A$16 | C31: ="Puntaje "&Inicio!$A$17 | D31: ="Puntaje "&Inicio!$A$18 | E31: Ganador
A32: 0 | B32: =$A32*Resultados!$C$16+(1-$A32)*(Resultados!$G$16-Resultados!$C$15*Resultados!$C$16)/(1-Resultados!$C$15) | C32: =$A32*Resultados!$C$17+(1-$A32)*(Resultados!$G$17-Resultados!$C$15*Resultados!$C$17)/(1-Resultados!$C$15) | D32: =$A32*Resultados!$C$18+(1-$A32)*(Resultados!$G$18-Resultados!$C$15*Resultados!$C$18)/(1-Resultados!$C$15) | E32: {=IF(INDEX(B32:D32,Sensibilidad!$B$37)>=MAX(B32:D32)-0.0000001,Sensibilidad!$C$37,INDEX(Inicio!$A$16:$A$18,MATCH(MAX(B32:D32),B32:D32,0)))}
A33: 0.05 | B33: =$A33*Resultados!$C$16+(1-$A33)*(Resultados!$G$16-Resultados!$C$15*Resultados!$C$16)/(1-Resultados!$C$15) | C33: =$A33*Resultados!$C$17+(1-$A33)*(Resultados!$G$17-Resultados!$C$15*Resultados!$C$17)/(1-Resultados!$C$15) | D33: =$A33*Resultados!$C$18+(1-$A33)*(Resultados!$G$18-Resultados!$C$15*Resultados!$C$18)/(1-Resultados!$C$15) | E33: {=IF(INDEX(B33:D33,Sensibilidad!$B$37)>=MAX(B33:D33)-0.0000001,Sensibilidad!$C$37,INDEX(Inicio!$A$16:$A$18,MATCH(MAX(B33:D33),B33:D33,0)))}
A34: 0.1 | B34: =$A34*Resultados!$C$16+(1-$A34)*(Resultados!$G$16-Resultados!$C$15*Resultados!$C$16)/(1-Resultados!$C$15) | C34: =$A34*Resultados!$C$17+(1-$A34)*(Resultados!$G$17-Resultados!$C$15*Resultados!$C$17)/(1-Resultados!$C$15) | D34: =$A34*Resultados!$C$18+(1-$A34)*(Resultados!$G$18-Resultados!$C$15*Resultados!$C$18)/(1-Resultados!$C$15) | E34: {=IF(INDEX(B34:D34,Sensibilidad!$B$37)>=MAX(B34:D34)-0.0000001,Sensibilidad!$C$37,INDEX(Inicio!$A$16:$A$18,MATCH(MAX(B34:D34),B34:D34,0)))}
A35: 0.15 | B35: =$A35*Resultados!$C$16+(1-$A35)*(Resultados!$G$16-Resultados!$C$15*Resultados!$C$16)/(1-Resultados!$C$15) | C35: =$A35*Resultados!$C$17+(1-$A35)*(Resultados!$G$17-Resultados!$C$15*Resultados!$C$17)/(1-Resultados!$C$15) | D35: =$A35*Resultados!$C$18+(1-$A35)*(Resultados!$G$18-Resultados!$C$15*Resultados!$C$18)/(1-Resultados!$C$15) | E35: {=IF(INDEX(B35:D35,Sensibilidad!$B$37)>=MAX(B35:D35)-0.0000001,Sensibilidad!$C$37,INDEX(Inicio!$A$16:$A$18,MATCH(MAX(B35:D35),B35:D35,0)))}
